Workbook

Sheet SETS
F2: OSeMOSYS_UCLV
F3: SETS | G3: Index
F4: REGION | G4: R | K4: Edit
F5: TECHNOLOGIES | G5: T | K5: Edit
F6: FUELS | G6: F | K6: Edit
F7: YEARS | G7: Y
F8: DAYTYPE | G8: LD
F9: DAILYTIMEBRACKET | G9: LH
F10: SEASON | G10: LS
F11: TIMESLICE | G11: L | K11: Edit
F12: MODE_OF_OPERATION | G12: M | K12: Edit
F13: STORAGE | G13: S | K13: Edit
F14: EMISSION | G14: E | K14: Edit
F15: FLEXIBLEDEMANDTYPE | K15: Edit

Sheet Parameters
B2: Demands | C2: Performance | D2: Costs | E2: Storage
B3: SpecifiedAnnualDemand | C3: CapacityToActivityUnit | D3: CapitalCost | E3: TechnologyToStorage
B4: SpecifiedDemandProfile | C4: CapacityFactor | D4: VariableCost | E4: TechnologyFromStorage
B5: AccumulatedAnnualDemand | C5: AvailabilityFactor | D5: FixedCost | E5: StorageLevelStart
C6: OperationalLife | E6: StorageMaxChargeRate
C7: ResidualCapacity | E7: StorageMaxDischargeRate
C8: InputActivityRatio | E8: MinStorageCharge
C9: OutputActivityRatio | E9: OperationalLifeStorage
E10: CapitalCostStorage
E11: ResidualStorageCapacity
B14: Capacity | C14: Activity | D14: Reserve Margin | E14: New Parameters
B15: CapacityOfOneTechnologyUnit | C15: TotalTechnologyAnnualActivityUpperLimit | D15: ReserveMarginTagTechnology | E15: MinOperatingLoad
B16: TotalAnnualMaxCapacity | C16: TotalTechnologyAnnualActivityLowerLimit | D16: ReserveMarginTagFuel | E16: Non Asociated Cost
B17: TotalAnnualMinCapacity | C17: TotalTechnologyModelPeriodActivityUpperLimit | D17: ReserveMargin | E17: NumberOfExistingUnits
B18: TotalAnnualMaxCapacityInvestment | C18: TotalTechnologyModelPeriodActivityLowerLimit | E18: RecoverCost
B19: TotalAnnualMinCapacityInvestment | E19: ExtendedOperationalLife
E20: Availability
E21: Maintenance
B22: RE Generation target | C22: Emissions | D22: GlobalParameters
B23: RETagTechnology | C23: EmissionActivityRatio | D23: YearSplit
B24: RETagFuel | C24: EmissionsPenalty | D24: DaySplit
B25: REMinProductionTarget | C25: AnnualExogenousEmission
C26: AnnualEmissionLimit
C27: ModelPeriodExogenousEmission
C28: ModelPeriodEmissionLimit

Sheet Default Parameters
A1: Parameter | B1: Unit | C1: Defaul value
A2: Global
A3: DiscountRate | C3: 0.05
A4: DepreciationMethod | C4: 1
A5: DaySplit | C5: =12/(24*365) -> 0.001369863
A6: Conversionls | C6: 0
A7: Conversionld | C7: 0
A8: Conversionlh | C8: 0
A9: DaysInDayType | C9: 7
A10: TradeRoute | C10: 0
A11: Demands
A12: SpecifiedAnnualDemand | B12: PJ | C12: 0
A13: SpecifiedDemandProfile | C13: 0
A14: AccumulatedAnnualDemand | C14: 0
A15: Performance
A16: CapacityToActivityUnit | C16: 1
A17: CapacityFactor | C17: 1
A18: AvailabilityFactor | C18: 1
A19: OperationalLife | B19: Year | C19: 1
A20: ResidualCapacity | B20: GW | C20: 0
A21: InputActivityRatio | C21: 0
A22: OutputActivityRatio | C22: 0
A23: Technology Costs
A24: CapitalCost | B24: Million $/GW | C24: 0.0001
A25: VariableCost | B25: M$/PJ or $/GWh | C25: 0
A26: FixedCost | B26: Million $/GW | C26: 0
A27: Storage
A28: MinStorageCharge | B28: PJ | C28: 0
A29: TechnologyToStorage | C29: 0
A30: TechnologyFromStorage | C30: 0
A31: StorageLevelStart | C31: 0
A32: StorageMaxChargeRate | B32: PJ | C32: 99999
A33: StorageMaxDischargeRate | B33: PJ | C33: 99999
A34: OperationalLifeStorage | B34: Year | C34: 99
A35: CapitalCostStorage | B35: Million $/GW | C35: 0
A36: ResidualStorageCapacity | B36: GW | C36: 0
A37: Capacity
A38: CapacityOfOneTechnologyUnit | C38: 0
A39: TotalAnnualMaxCapacity | B39: GW | C39: 99999999999
A40: TotalAnnualMinCapacity | B40: GW | C40: 0
...

Sheet R
A1: REGION | B1: Description
A2: Cuba

Sheet Y
A1: YEAR | B1: GROUP | C1: START_YEAR | D1: FINAL_YEAR
A2: =C2 -> 2019 | C2: 2019 | D2: 2055 | F2: 1
A3: =IF($A$2+F2>$D$2,"",$A$2+F2) -> 2020 | F3: 2
A4: =IF($A$2+F3>$D$2,"",$A$2+F3) -> 2021 | F4: 3
A5: =IF($A$2+F4>$D$2,"",$A$2+F4) -> 2022 | F5: 4
A6: =IF($A$2+F5>$D$2,"",$A$2+F5) -> 2023 | F6: 5
A7: =IF($A$2+F6>$D$2,"",$A$2+F6) -> 2024 | F7: 6
A8: =IF($A$2+F7>$D$2,"",$A$2+F7) -> 2025 | F8: 7
A9: =IF($A$2+F8>$D$2,"",$A$2+F8) -> 2026 | F9: 8
A10: =IF($A$2+F9>$D$2,"",$A$2+F9) -> 2027 | F10: 9
A11: =IF($A$2+F10>$D$2,"",$A$2+F10) -> 2028 | F11: 10
A12: =IF($A$2+F11>$D$2,"",$A$2+F11) -> 2029 | F12: 11
A13: =IF($A$2+F12>$D$2,"",$A$2+F12) -> 2030 | F13: 12
A14: =IF($A$2+F13>$D$2,"",$A$2+F13) -> 2031 | F14: 13
... A45: =IF($A$2+F44>$D$2,"",$A$2+F44) | F45: 44

Sheet T
A1: TECHNOLOGY | B1: Description | C1: Group
A2: IMPCRUDE | B2: CrudeOil
A3: MINCRUDE | B3: Mining
A4: IMPHFO01 | B4: Heavy Fuel oil for CTE
A5: IMPHFO02 | B5: Heavy Fuel oir for movil Generators
A6: IMPLFO | B6: Ligth Fuel Oil for MCI
A7: MINDIESEL | B7: Diesel - National
A8: IMPDIESEL | B8: Import Diesel For Diesel MCI
A9: IMPNG | B9: Import Natural Gas (GNL)
A10: MINNG | B10: Natural gas - National
A11: MINBIO1 | B11: Bagazo
A12: MINBIO2 | B12: Marabu | C12: exclude
A13: MINBIO3 | B13: Firewood (Leña cocción) | C13: exclude
A14: MINBIO4 | B14: Carbón vegetal | C14: exclude
A15: IMPBIO | B15: Biomasa importada | C15: exclude
A16: MINKEROSEN | B16: Kerosene (Queroseno) | C16: exclude
A17: IMPKEROSEN | B17: Kerosene (Queroseno) | C17: exclude
A18: MINALCOHOL | B18: Alcohol Production for cooking | C18: exclude
A19: MINGASOLINE | B19: Gasoline | C19: exclude
A20: IMPGASOLINE | B20: Gasoline | C20: exclude
A21: MINSOL | B21: Solar potential | C21: exclude
A22: MINWIND | B22: Wind potential | C22: exclude
A23: MINHYDRO | B23: Hydro potential
A24: PWRCRUD001 | B24: Old CrudeOil Power plant
A25: PWRCRUD002 | B25: Old CrudeOil Power plant
A26: PWRCRUD003 | B26: Old CrudeOil Power plant
A27: PWRCRUD004 | B27: Old CrudeOil Power plant
A28: PWRCRUD008 | B28: Old CrudeOil Power plant
A29: PWRCRUD005 | B29: Old CrudeOil Power plant
A30: PWRCRUD006 | B30: Old CrudeOil Power plant
A31: PWRCRUD007 | B31: Old CrudeOil Power plant
A32: PWRCRUD009 | B32: New CrudeOil Power plant (200 MW/unit)
A33: PWRNG01 | B33: Natural Gas Power Plant (combined cycle)
A34: PWRNG02 | B34: Natural Gas Power Plant (combined cycle)
... A38: PWRWND001 | B38: Wind onshore
A39: PWRWND002 | B39: Wind OffShore | C39: exclude
A40: PWRPV01 | B40: Fotovoltáica
A41: PWRPV02 | B41: FotovoltáicaResidencial | C41: exclude
A42: PWRPV03 | B42: PV+ | C42: exclude
A43: PWRCSP | B43: Concentradores solares
...

Sheet F
A1: FUEL | B1: Description | C1: Group
A2: CRUD | B2: Crude Oil
A3: HFO01 | B3: Heavy Fuel Oil for CTE
A4: HFO02 | B4: Heavy Fuel Oil for Movil Generators
A5: LFO | B5: Ligth Fuel Oil for MCI
A6: DSL | B6: Diesel for MCI
A7: NG | B7: Gas natural
A8: BIO01 | B8: Bagazo
A9: BIO02 | B9: Marabu | C9: exclude
A10: BIO03 | B10: Firewood (Leña cocción) | C10: exclude
A11: BIO04 | B11: Carbón vegetal | C11: exclude
A12: GASOLINE | C12: exclude
A13: KEROSENE | C13: exclude
A14: ALCOHOL | C14: exclude
A15: SOL | B15: Solar
A16: WND | B16: Wind
A17: HYD | B17: Hydro
A18: ELC01 | B18: Electricidad de las plantas térmicas a la transmisión
A19: ELC02 | B19: Electricidad después de la transmission
A20: ELC03 | B20: Electricidad después de la distribución
A21: ELCSTORAGE01 | B21: Electricity to Storage after transmition | C21: exclude
A22: ELCSTORAGE02 | B22: Electricity to storage Distribution | C22: exclude
A23: ELCEV | B23: Electric vehicles | C23: exclude
A24: TRAMCY | B24: Motorcycle Transport Demand | C24: exclude
A25: TRACAR | B25: Car Transport Demand | C25: exclude
A26: TRABUS | B26: Bus + Rail Transport Demand | C26: exclude
A27: TRAFREIGTH | B27: Cargo demand | C27: exclude
A28: INDELC | B28: Industrial Electricity Demand | C28: exclude
A29: INDHEH | B29: Industry High Heat Demand | C29: exclude
A30: INDHEL | B30: Industry Low Heat Demand | C30: exclude
A31: RESELC | B31: Residential Electricity Demand
A32: RESCKN | B32: Residential Cooking Demand | C32: exclude
A33: RESHEL | B33: Residential Low Heat Demand | C33: exclude
A34: COMELC | B34: Commercial Electricity Demand
A35: COMHEL | B35: Commercial Low Heat Demand | C35: exclude
A36: LIGTHELEC | B36: Demanda Alumbrado | C36: exclude
A37: CRUDEXP | C37: exclude
A38: GASLIQ | C38: exclude
A39: TRACAMDMY | C39: exclude
A40: TRACARDMY | C40: exclude
...

Sheet LS
A1: SEASON | B1: Description
A2: 1
A3: 2
A4: 3
A5: 4

Sheet LD
A1: DAYTYPE | B1: Description
A2: 1 | B2: Trabajo
A3: 2

Sheet LH
A1: DAILYTIMEBRACKET | B1: Description
A2: 1
A3: 2
A4: 3
A5: 4
A6: 5
A7: 6
A8: 7
A9: 8

Sheet L
A1: TIMESLICE | B1: Description
A2: 111
A3: 112
A4: 113
A5: 114
A6: 115
A7: 116
A8: 117
A9: 118
A10: 121
A11: 122
A12: 123
A13: 124
... A65: 428

Sheet M
A1: ModeOfOperation
A2: 1
A3: 2

Sheet S
A1: STORAGE | B1: Description
A2: DAM | B2: DAM Storage
A3: Batt01 | B3: Electric Battery
A4: Batt02 | B4: Electric Battery
A5: Batt03
A6: Batt04
A7: Batt05

Sheet E
A1: EMISSION | B1: Description | T1: EMISSION | U1: Description
A2: CO2 | T2: CO2
A3: Nox | T3: Nox
A4: CH4 | T4: CH4

Sheet FLEX

Sheet DS
A1: DAILYTIMEBRACKET | B1: 2019 | C1: 2020 | D1: 2021 | E1: 2022 | F1: 2023 | G1: 2024 | H1: 2025 | I1: 2026 | J1: 2027 | K1: 2028 | L1: 2029 | M1: 2030 | N1: 2031 | O1: 2032 | P1: 2033 | Q1: 2034 | R1: 2035 | S1: 2036 | T1: 2037 | U1: 2038 | V1: 2039 | W1: 2040 | X1: 2041 | Y1: 2042 | Z1: 2043 | AA1: 2044 | AB1: 2045 | AC1: 2046 | AD1: 2047 | AE1: 2048 | AF1: 2049 | AG1: 2050 | AH1: 2051 | AI1: 2052 | AJ1: 2053 | AK1: 2054 | AL1: 2055
A2: 1 | B2: 0.00057077626 | C2: 0.00057077626 | D2: 0.00057077626 | E2: 0.00057077626 | F2: 0.00057077626 | G2: 0.00057077626 | H2: 0.00057077626 | I2: 0.00057077626 | J2: 0.00057077626 | K2: 0.00057077626 | L2: 0.00057077626 | M2: 0.00057077626 | N2: 0.00057077626 | O2: 0.00057077626 | P2: 0.00057077626 | Q2: 0.00057077626 | R2: 0.00057077626 | S2: 0.00057077626 | T2: 0.00057077626 | U2: 0.00057077626 | V2: 0.00057077626 | W2: 0.00057077626 | X2: 0.00057077626 | Y2: 0.00057077626 | Z2: 0.00057077626 | AA2: 0.00057077626 | AB2: 0.00057077626 | AC2: 0.00057077626 | AD2: 0.00057077626 | AE2: 0.00057077626 | AF2: 0.00057077626 | AG2: 0.00057077626 | AH2: 0.00057077626 | AI2: 0.00057077626 | AJ2: 0.00057077626 | AK2: 0.00057077626 | AL2: 0.00057077626
A3: 2 | B3: 0.00057077626 | C3: 0.00057077626 | D3: 0.00057077626 | E3: 0.00057077626 | F3: 0.00057077626 | G3: 0.00057077626 | H3: 0.00057077626 | I3: 0.00057077626 | J3: 0.00057077626 | K3: 0.00057077626 | L3: 0.00057077626 | M3: 0.00057077626 | N3: 0.00057077626 | O3: 0.00057077626 | P3: 0.00057077626 | Q3: 0.00057077626 | R3: 0.00057077626 | S3: 0.00057077626 | T3: 0.00057077626 | U3: 0.00057077626 | V3: 0.00057077626 | W3: 0.00057077626 | X3: 0.00057077626 | Y3: 0.00057077626 | Z3: 0.00057077626 | AA3: 0.00057077626 | AB3: 0.00057077626 | AC3: 0.00057077626 | AD3: 0.00057077626 | AE3: 0.00057077626 | AF3: 0.00057077626 | AG3: 0.00057077626 | AH3: 0.00057077626 | AI3: 0.00057077626 | AJ3: 0.00057077626 | AK3: 0.00057077626 | AL3: 0.00057077626
A4: 3 | B4: 0.0002283105 | C4: 0.0002283105 | D4: 0.0002283105 | E4: 0.0002283105 | F4: 0.0002283105 | G4: 0.0002283105 | H4: 0.0002283105 | I4: 0.0002283105 | J4: 0.0002283105 | K4: 0.0002283105 | L4: 0.0002283105 | M4: 0.0002283105 | N4: 0.0002283105 | O4: 0.0002283105 | P4: 0.0002283105 | Q4: 0.0002283105 | R4: 0.0002283105 | S4: 0.0002283105 | T4: 0.0002283105 | U4: 0.0002283105 | V4: 0.0002283105 | W4: 0.0002283105 | X4: 0.0002283105 | Y4: 0.0002283105 | Z4: 0.0002283105 | AA4: 0.0002283105 | AB4: 0.0002283105 | AC4: 0.0002283105 | AD4: 0.0002283105 | AE4: 0.0002283105 | AF4: 0.0002283105 | AG4: 0.0002283105 | AH4: 0.0002283105 | AI4: 0.0002283105 | AJ4: 0.0002283105 | AK4: 0.0002283105 | AL4: 0.0002283105
A5: 4 | B5: 0.00034246575 | C5: 0.00034246575 | D5: 0.00034246575 | E5: 0.00034246575 | F5: 0.00034246575 | G5: 0.00034246575 | H5: 0.00034246575 | I5: 0.00034246575 | J5: 0.00034246575 | K5: 0.00034246575 | L5: 0.00034246575 | M5: 0.00034246575 | N5: 0.00034246575 | O5: 0.00034246575 | P5: 0.00034246575 | Q5: 0.00034246575 | R5: 0.00034246575 | S5: 0.00034246575 | T5: 0.00034246575 | U5: 0.00034246575 | V5: 0.00034246575 | W5: 0.00034246575 | X5: 0.00034246575 | Y5: 0.00034246575 | Z5: 0.00034246575 | AA5: 0.00034246575 | AB5: 0.00034246575 | AC5: 0.00034246575 | AD5: 0.00034246575 | AE5: 0.00034246575 | AF5: 0.00034246575 | AG5: 0.00034246575 | AH5: 0.00034246575 | AI5: 0.00034246575 | AJ5: 0.00034246575 | AK5: 0.00034246575 | AL5: 0.00034246575
A6: 5 | B6: 0.0002283105 | C6: 0.0002283105 | D6: 0.0002283105 | E6: 0.0002283105 | F6: 0.0002283105 | G6: 0.0002283105 | H6: 0.0002283105 | I6: 0.0002283105 | J6: 0.0002283105 | K6: 0.0002283105 | L6: 0.0002283105 | M6: 0.0002283105 | N6: 0.0002283105 | O6: 0.0002283105 | P6: 0.0002283105 | Q6: 0.0002283105 | R6: 0.0002283105 | S6: 0.0002283105 | T6: 0.0002283105 | U6: 0.0002283105 | V6: 0.0002283105 | W6: 0.0002283105 | X6: 0.0002283105 | Y6: 0.0002283105 | Z6: 0.0002283105 | AA6: 0.0002283105 | AB6: 0.0002283105 | AC6: 0.0002283105 | AD6: 0.0002283105 | AE6: 0.0002283105 | AF6: 0.0002283105 | AG6: 0.0002283105 | AH6: 0.0002283105 | AI6: 0.0002283105 | AJ6: 0.0002283105 | AK6: 0.0002283105 | AL6: 0.0002283105
A7: 6 | B7: 0.00034246575 | C7: 0.00034246575 | D7: 0.00034246575 | E7: 0.00034246575 | F7: 0.00034246575 | G7: 0.00034246575 | H7: 0.00034246575 | I7: 0.00034246575 | J7: 0.00034246575 | K7: 0.00034246575 | L7: 0.00034246575 | M7: 0.00034246575 | N7: 0.00034246575 | O7: 0.00034246575 | P7: 0.00034246575 | Q7: 0.00034246575 | R7: 0.00034246575 | S7: 0.00034246575 | T7: 0.00034246575 | U7: 0.00034246575 | V7: 0.00034246575 | W7: 0.00034246575 | X7: 0.00034246575 | Y7: 0.00034246575 | Z7: 0.00034246575 | AA7: 0.00034246575 | AB7: 0.00034246575 | AC7: 0.00034246575 | AD7: 0.00034246575 | AE7: 0.00034246575 | AF7: 0.00034246575 | AG7: 0.00034246575 | AH7: 0.00034246575 | AI7: 0.00034246575 | AJ7: 0.00034246575 | AK7: 0.00034246575 | AL7: 0.00034246575
A8: 7 | B8: 0.0002283105 | C8: 0.0002283105 | D8: 0.0002283105 | E8: 0.0002283105 | F8: 0.0002283105 | G8: 0.0002283105 | H8: 0.0002283105 | I8: 0.0002283105 | J8: 0.0002283105 | K8: 0.0002283105 | L8: 0.0002283105 | M8: 0.0002283105 | N8: 0.0002283105 | O8: 0.0002283105 | P8: 0.0002283105 | Q8: 0.0002283105 | R8: 0.0002283105 | S8: 0.0002283105 | T8: 0.0002283105 | U8: 0.0002283105 | V8: 0.0002283105 | W8: 0.0002283105 | X8: 0.0002283105 | Y8: 0.0002283105 | Z8: 0.0002283105 | AA8: 0.0002283105 | AB8: 0.0002283105 | AC8: 0.0002283105 | AD8: 0.0002283105 | AE8: 0.0002283105 | AF8: 0.0002283105 | AG8: 0.0002283105 | AH8: 0.0002283105 | AI8: 0.0002283105 | AJ8: 0.0002283105 | AK8: 0.0002283105 | AL8: 0.0002283105
A9: 8 | B9: 0.0002283105 | C9: 0.0002283105 | D9: 0.0002283105 | E9: 0.0002283105 | F9: 0.0002283105 | G9: 0.0002283105 | H9: 0.0002283105 | I9: 0.0002283105 | J9: 0.0002283105 | K9: 0.0002283105 | L9: 0.0002283105 | M9: 0.0002283105 | N9: 0.0002283105 | O9: 0.0002283105 | P9: 0.0002283105 | Q9: 0.0002283105 | R9: 0.0002283105 | S9: 0.0002283105 | T9: 0.0002283105 | U9: 0.0002283105 | V9: 0.0002283105 | W9: 0.0002283105 | X9: 0.0002283105 | Y9: 0.0002283105 | Z9: 0.0002283105 | AA9: 0.0002283105 | AB9: 0.0002283105 | AC9: 0.0002283105 | AD9: 0.0002283105 | AE9: 0.0002283105 | AF9: 0.0002283105 | AG9: 0.0002283105 | AH9: 0.0002283105 | AI9: 0.0002283105 | AJ9: 0.0002283105 | AK9: 0.0002283105 | AL9: 0.0002283105

Sheet DIDT
A1: SEASON | B1: DAYTYPE | C1: 2019 | D1: 2020 | E1: 2021 | F1: 2022 | G1: 2023 | H1: 2024 | I1: 2025 | J1: 2026 | K1: 2027 | L1: 2028 | M1: 2029 | N1: 2030 | O1: 2031 | P1: 2032 | Q1: 2033 | R1: 2034 | S1: 2035 | T1: 2036 | U1: 2037 | V1: 2038 | W1: 2039 | X1: 2040 | Y1: 2041 | Z1: 2042 | AA1: 2043 | AB1: 2044 | AC1: 2045 | AD1: 2046 | AE1: 2047 | AF1: 2048 | AG1: 2049 | AH1: 2050 | AI1: 2051 | AJ1: 2052 | AK1: 2053 | AL1: 2054 | AM1: 2055
A2: 1 | B2: 1 | C2: 5 | D2: 5 | E2: 5 | F2: 5 | G2: 5 | H2: 5 | I2: 5 | J2: 5 | K2: 5 | L2: 5 | M2: 5 | N2: 5 | O2: 5 | P2: 5 | Q2: 5 | R2: 5 | S2: 5 | T2: 5 | U2: 5 | V2: 5 | W2: 5 | X2: 5 | Y2: 5 | Z2: 5 | AA2: 5 | AB2: 5 | AC2: 5 | AD2: 5 | AE2: 5 | AF2: 5 | AG2: 5 | AH2: 5 | AI2: 5 | AJ2: 5 | AK2: 5 | AL2: 5 | AM2: 5
A3: 1 | B3: 2 | C3: 2 | D3: 2 | E3: 2 | F3: 2 | G3: 2 | H3: 2 | I3: 2 | J3: 2 | K3: 2 | L3: 2 | M3: 2 | N3: 2 | O3: 2 | P3: 2 | Q3: 2 | R3: 2 | S3: 2 | T3: 2 | U3: 2 | V3: 2 | W3: 2 | X3: 2 | Y3: 2 | Z3: 2 | AA3: 2 | AB3: 2 | AC3: 2 | AD3: 2 | AE3: 2 | AF3: 2 | AG3: 2 | AH3: 2 | AI3: 2 | AJ3: 2 | AK3: 2 | AL3: 2 | AM3: 2
A4: 2 | B4: 1 | C4: 5 | D4: 5 | E4: 5 | F4: 5 | G4: 5 | H4: 5 | I4: 5 | J4: 5 | K4: 5 | L4: 5 | M4: 5 | N4: 5 | O4: 5 | P4: 5 | Q4: 5 | R4: 5 | S4: 5 | T4: 5 | U4: 5 | V4: 5 | W4: 5 | X4: 5 | Y4: 5 | Z4: 5 | AA4: 5 | AB4: 5 | AC4: 5 | AD4: 5 | AE4: 5 | AF4: 5 | AG4: 5 | AH4: 5 | AI4: 5 | AJ4: 5 | AK4: 5 | AL4: 5 | AM4: 5
A5: 2 | B5: 2 | C5: 2 | D5: 2 | E5: 2 | F5: 2 | G5: 2 | H5: 2 | I5: 2 | J5: 2 | K5: 2 | L5: 2 | M5: 2 | N5: 2 | O5: 2 | P5: 2 | Q5: 2 | R5: 2 | S5: 2 | T5: 2 | U5: 2 | V5: 2 | W5: 2 | X5: 2 | Y5: 2 | Z5: 2 | AA5: 2 | AB5: 2 | AC5: 2 | AD5: 2 | AE5: 2 | AF5: 2 | AG5: 2 | AH5: 2 | AI5: 2 | AJ5: 2 | AK5: 2 | AL5: 2 | AM5: 2
A6: 3 | B6: 1 | C6: 5 | D6: 5 | E6: 5 | F6: 5 | G6: 5 | H6: 5 | I6: 5 | J6: 5 | K6: 5 | L6: 5 | M6: 5 | N6: 5 | O6: 5 | P6: 5 | Q6: 5 | R6: 5 | S6: 5 | T6: 5 | U6: 5 | V6: 5 | W6: 5 | X6: 5 | Y6: 5 | Z6: 5 | AA6: 5 | AB6: 5 | AC6: 5 | AD6: 5 | AE6: 5 | AF6: 5 | AG6: 5 | AH6: 5 | AI6: 5 | AJ6: 5 | AK6: 5 | AL6: 5 | AM6: 5
A7: 3 | B7: 2 | C7: 2 | D7: 2 | E7: 2 | F7: 2 | G7: 2 | H7: 2 | I7: 2 | J7: 2 | K7: 2 | L7: 2 | M7: 2 | N7: 2 | O7: 2 | P7: 2 | Q7: 2 | R7: 2 | S7: 2 | T7: 2 | U7: 2 | V7: 2 | W7: 2 | X7: 2 | Y7: 2 | Z7: 2 | AA7: 2 | AB7: 2 | AC7: 2 | AD7: 2 | AE7: 2 | AF7: 2 | AG7: 2 | AH7: 2 | AI7: 2 | AJ7: 2 | AK7: 2 | AL7: 2 | AM7: 2
A8: 4 | B8: 1 | C8: 5 | D8: 5 | E8: 5 | F8: 5 | G8: 5 | H8: 5 | I8: 5 | J8: 5 | K8: 5 | L8: 5 | M8: 5 | N8: 5 | O8: 5 | P8: 5 | Q8: 5 | R8: 5 | S8: 5 | T8: 5 | U8: 5 | V8: 5 | W8: 5 | X8: 5 | Y8: 5 | Z8: 5 | AA8: 5 | AB8: 5 | AC8: 5 | AD8: 5 | AE8: 5 | AF8: 5 | AG8: 5 | AH8: 5 | AI8: 5 | AJ8: 5 | AK8: 5 | AL8: 5 | AM8: 5
A9: 4 | B9: 2 | C9: 2 | D9: 2 | E9: 2 | F9: 2 | G9: 2 | H9: 2 | I9: 2 | J9: 2 | K9: 2 | L9: 2 | M9: 2 | N9: 2 | O9: 2 | P9: 2 | Q9: 2 | R9: 2 | S9: 2 | T9: 2 | U9: 2 | V9: 2 | W9: 2 | X9: 2 | Y9: 2 | Z9: 2 | AA9: 2 | AB9: 2 | AC9: 2 | AD9: 2 | AE9: 2 | AF9: 2 | AG9: 2 | AH9: 2 | AI9: 2 | AJ9: 2 | AK9: 2 | AL9: 2 | AM9: 2

Sheet YS
A1: TIMESLICE | B1: 2019 | C1: 2020 | D1: 2021 | E1: 2022 | F1: 2023 | G1: 2024 | H1: 2025 | I1: 2026 | J1: 2027 | K1: 2028 | L1: 2029 | M1: 2030 | N1: 2031 | O1: 2032 | P1: 2033 | Q1: 2034 | R1: 2035 | S1: 2036 | T1: 2037 | U1: 2038 | V1: 2039 | W1: 2040 | X1: 2041 | Y1: 2042 | Z1: 2043 | AA1: 2044 | AB1: 2045 | AC1: 2046 | AD1: 2047 | AE1: 2048 | AF1: 2049 | AG1: 2050 | AH1: 2051 | AI1: 2052 | AJ1: 2053 | AK1: 2054 | AL1: 2055
A2: 111 | B2: 0.026 | C2: 0.026 | D2: 0.026 | E2: 0.026 | F2: 0.026 | G2: 0.026 | H2: 0.026 | I2: 0.026 | J2: 0.026 | K2: 0.026 | L2: 0.026 | M2: 0.026 | N2: 0.026 | O2: 0.026 | P2: 0.026 | Q2: 0.026 | R2: 0.026 | S2: 0.026 | T2: 0.026 | U2: 0.026 | V2: 0.026 | W2: 0.026 | X2: 0.026 | Y2: 0.026 | Z2: 0.026 | AA2: 0.026 | AB2: 0.026 | AC2: 0.026 | AD2: 0.026 | AE2: 0.026 | AF2: 0.026 | AG2: 0.026 | AH2: 0.026 | AI2: 0.026 | AJ2: 0.026 | AK2: 0.026 | AL2: 0.026
A3: 112 | B3: 0.026 | C3: 0.026 | D3: 0.026 | E3: 0.026 | F3: 0.026 | G3: 0.026 | H3: 0.026 | I3: 0.026 | J3: 0.026 | K3: 0.026 | L3: 0.026 | M3: 0.026 | N3: 0.026 | O3: 0.026 | P3: 0.026 | Q3: 0.026 | R3: 0.026 | S3: 0.026 | T3: 0.026 | U3: 0.026 | V3: 0.026 | W3: 0.026 | X3: 0.026 | Y3: 0.026 | Z3: 0.026 | AA3: 0.026 | AB3: 0.026 | AC3: 0.026 | AD3: 0.026 | AE3: 0.026 | AF3: 0.026 | AG3: 0.026 | AH3: 0.026 | AI3: 0.026 | AJ3: 0.026 | AK3: 0.026 | AL3: 0.026
A4: 113 | B4: 0.01 | C4: 0.01 | D4: 0.01 | E4: 0.01 | F4: 0.01 | G4: 0.01 | H4: 0.01 | I4: 0.01 | J4: 0.01 | K4: 0.01 | L4: 0.01 | M4: 0.01 | N4: 0.01 | O4: 0.01 | P4: 0.01 | Q4: 0.01 | R4: 0.01 | S4: 0.01 | T4: 0.01 | U4: 0.01 | V4: 0.01 | W4: 0.01 | X4: 0.01 | Y4: 0.01 | Z4: 0.01 | AA4: 0.01 | AB4: 0.01 | AC4: 0.01 | AD4: 0.01 | AE4: 0.01 | AF4: 0.01 | AG4: 0.01 | AH4: 0.01 | AI4: 0.01 | AJ4: 0.01 | AK4: 0.01 | AL4: 0.01
A5: 114 | B5: 0.015 | C5: 0.015 | D5: 0.015 | E5: 0.015 | F5: 0.015 | G5: 0.015 | H5: 0.015 | I5: 0.015 | J5: 0.015 | K5: 0.015 | L5: 0.015 | M5: 0.015 | N5: 0.015 | O5: 0.015 | P5: 0.015 | Q5: 0.015 | R5: 0.015 | S5: 0.015 | T5: 0.015 | U5: 0.015 | V5: 0.015 | W5: 0.015 | X5: 0.015 | Y5: 0.015 | Z5: 0.015 | AA5: 0.015 | AB5: 0.015 | AC5: 0.015 | AD5: 0.015 | AE5: 0.015 | AF5: 0.015 | AG5: 0.015 | AH5: 0.015 | AI5: 0.015 | AJ5: 0.015 | AK5: 0.015 | AL5: 0.015
A6: 115 | B6: 0.01 | C6: 0.01 | D6: 0.01 | E6: 0.01 | F6: 0.01 | G6: 0.01 | H6: 0.01 | I6: 0.01 | J6: 0.01 | K6: 0.01 | L6: 0.01 | M6: 0.01 | N6: 0.01 | O6: 0.01 | P6: 0.01 | Q6: 0.01 | R6: 0.01 | S6: 0.01 | T6: 0.01 | U6: 0.01 | V6: 0.01 | W6: 0.01 | X6: 0.01 | Y6: 0.01 | Z6: 0.01 | AA6: 0.01 | AB6: 0.01 | AC6: 0.01 | AD6: 0.01 | AE6: 0.01 | AF6: 0.01 | AG6: 0.01 | AH6: 0.01 | AI6: 0.01 | AJ6: 0.01 | AK6: 0.01 | AL6: 0.01
A7: 116 | B7: 0.015 | C7: 0.015 | D7: 0.015 | E7: 0.015 | F7: 0.015 | G7: 0.015 | H7: 0.015 | I7: 0.015 | J7: 0.015 | K7: 0.015 | L7: 0.015 | M7: 0.015 | N7: 0.015 | O7: 0.015 | P7: 0.015 | Q7: 0.015 | R7: 0.015 | S7: 0.015 | T7: 0.015 | U7: 0.015 | V7: 0.015 | W7: 0.015 | X7: 0.015 | Y7: 0.015 | Z7: 0.015 | AA7: 0.015 | AB7: 0.015 | AC7: 0.015 | AD7: 0.015 | AE7: 0.015 | AF7: 0.015 | AG7: 0.015 | AH7: 0.015 | AI7: 0.015 | AJ7: 0.015 | AK7: 0.015 | AL7: 0.015
A8: 117 | B8: 0.01 | C8: 0.01 | D8: 0.01 | E8: 0.01 | F8: 0.01 | G8: 0.01 | H8: 0.01 | I8: 0.01 | J8: 0.01 | K8: 0.01 | L8: 0.01 | M8: 0.01 | N8: 0.01 | O8: 0.01 | P8: 0.01 | Q8: 0.01 | R8: 0.01 | S8: 0.01 | T8: 0.01 | U8: 0.01 | V8: 0.01 | W8: 0.01 | X8: 0.01 | Y8: 0.01 | Z8: 0.01 | AA8: 0.01 | AB8: 0.01 | AC8: 0.01 | AD8: 0.01 | AE8: 0.01 | AF8: 0.01 | AG8: 0.01 | AH8: 0.01 | AI8: 0.01 | AJ8: 0.01 | AK8: 0.01 | AL8: 0.01
A9: 118 | B9: 0.01 | C9: 0.01 | D9: 0.01 | E9: 0.01 | F9: 0.01 | G9: 0.01 | H9: 0.01 | I9: 0.01 | J9: 0.01 | K9: 0.01 | L9: 0.01 | M9: 0.01 | N9: 0.01 | O9: 0.01 | P9: 0.01 | Q9: 0.01 | R9: 0.01 | S9: 0.01 | T9: 0.01 | U9: 0.01 | V9: 0.01 | W9: 0.01 | X9: 0.01 | Y9: 0.01 | Z9: 0.01 | AA9: 0.01 | AB9: 0.01 | AC9: 0.01 | AD9: 0.01 | AE9: 0.01 | AF9: 0.01 | AG9: 0.01 | AH9: 0.01 | AI9: 0.01 | AJ9: 0.01 | AK9: 0.01 | AL9: 0.01
A10: 121 | B10: 0.026 | C10: 0.026 | D10: 0.026 | E10: 0.026 | F10: 0.026 | G10: 0.026 | H10: 0.026 | I10: 0.026 | J10: 0.026 | K10: 0.026 | L10: 0.026 | M10: 0.026 | N10: 0.026 | O10: 0.026 | P10: 0.026 | Q10: 0.026 | R10: 0.026 | S10: 0.026 | T10: 0.026 | U10: 0.026 | V10: 0.026 | W10: 0.026 | X10: 0.026 | Y10: 0.026 | Z10: 0.026 | AA10: 0.026 | AB10: 0.026 | AC10: 0.026 | AD10: 0.026 | AE10: 0.026 | AF10: 0.026 | AG10: 0.026 | AH10: 0.026 | AI10: 0.026 | AJ10: 0.026 | AK10: 0.026 | AL10: 0.026
A11: 122 | B11: 0.026 | C11: 0.026 | D11: 0.026 | E11: 0.026 | F11: 0.026 | G11: 0.026 | H11: 0.026 | I11: 0.026 | J11: 0.026 | K11: 0.026 | L11: 0.026 | M11: 0.026 | N11: 0.026 | O11: 0.026 | P11: 0.026 | Q11: 0.026 | R11: 0.026 | S11: 0.026 | T11: 0.026 | U11: 0.026 | V11: 0.026 | W11: 0.026 | X11: 0.026 | Y11: 0.026 | Z11: 0.026 | AA11: 0.026 | AB11: 0.026 | AC11: 0.026 | AD11: 0.026 | AE11: 0.026 | AF11: 0.026 | AG11: 0.026 | AH11: 0.026 | AI11: 0.026 | AJ11: 0.026 | AK11: 0.026 | AL11: 0.026
A12: 123 | B12: 0.01 | C12: 0.01 | D12: 0.01 | E12: 0.01 | F12: 0.01 | G12: 0.01 | H12: 0.01 | I12: 0.01 | J12: 0.01 | K12: 0.01 | L12: 0.01 | M12: 0.01 | N12: 0.01 | O12: 0.01 | P12: 0.01 | Q12: 0.01 | R12: 0.01 | S12: 0.01 | T12: 0.01 | U12: 0.01 | V12: 0.01 | W12: 0.01 | X12: 0.01 | Y12: 0.01 | Z12: 0.01 | AA12: 0.01 | AB12: 0.01 | AC12: 0.01 | AD12: 0.01 | AE12: 0.01 | AF12: 0.01 | AG12: 0.01 | AH12: 0.01 | AI12: 0.01 | AJ12: 0.01 | AK12: 0.01 | AL12: 0.01
A13: 124 | B13: 0.015 | C13: 0.015 | D13: 0.015 | E13: 0.015 | F13: 0.015 | G13: 0.015 | H13: 0.015 | I13: 0.015 | J13: 0.015 | K13: 0.015 | L13: 0.015 | M13: 0.015 | N13: 0.015 | O13: 0.015 | P13: 0.015 | Q13: 0.015 | R13: 0.015 | S13: 0.015 | T13: 0.015 | U13: 0.015 | V13: 0.015 | W13: 0.015 | X13: 0.015 | Y13: 0.015 | Z13: 0.015 | AA13: 0.015 | AB13: 0.015 | AC13: 0.015 | AD13: 0.015 | AE13: 0.015 | AF13: 0.015 | AG13: 0.015 | AH13: 0.015 | AI13: 0.015 | AJ13: 0.015 | AK13: 0.015 | AL13: 0.015
... A65: 428 | B65: 0.006 | C65: 0.006 | D65: 0.006 | E65: 0.006 | F65: 0.006 | G65: 0.006 | H65: 0.006 | I65: 0.006 | J65: 0.006 | K65: 0.006 | L65: 0.006 | M65: 0.006 | N65: 0.006 | O65: 0.006 | P65: 0.006 | Q65: 0.006 | R65: 0.006 | S65: 0.006 | T65: 0.006 | U65: 0.006 | V65: 0.006 | W65: 0.006 | X65: 0.006 | Y65: 0.006 | Z65: 0.006 | AA65: 0.006 | AB65: 0.006 | AC65: 0.006 | AD65: 0.006 | AE65: 0.006 | AF65: 0.006 | AG65: 0.006 | AH65: 0.006 | AI65: 0.006 | AJ65: 0.006 | AK65: 0.006 | AL65: 0.006

Sheet SAD
A1: REGION | B1: FUEL | C1: 2019 | D1: 2020 | E1: 2021 | F1: 2022 | G1: 2023 | H1: 2024 | I1: 2025 | J1: 2026 | K1: 2027 | L1: 2028 | M1: 2029 | N1: 2030 | O1: 2031 | P1: 2032 | Q1: 2033 | R1: 2034 | S1: 2035 | T1: 2036 | U1: 2037 | V1: 2038 | W1: 2039 | X1: 2040 | Y1: 2041 | Z1: 2042 | AA1: 2043 | AB1: 2044 | AC1: 2045 | AD1: 2046 | AE1: 2047 | AF1: 2048 | AG1: 2049 | AH1: 2050 | AI1: 2051 | AJ1: 2052 | AK1: 2053 | AL1: 2054 | AM1: 2055
A2: Cuba | B2: CRUD
A3: Cuba | B3: HFO01
A4: Cuba | B4: HFO02
A5: Cuba | B5: LFO
A6: Cuba | B6: DSL
A7: Cuba | B7: NG
A8: Cuba | B8: BIO01
A9: Cuba | B9: BIO02
A10: Cuba | B10: BIO03
A11: Cuba | B11: BIO04
A12: Cuba | B12: GASOLINE
A13: Cuba | B13: KEROSENE
... A30: Cuba | B30: INDHEL
A31: Cuba | B31: RESELC | C31: 31.25 | D31: 33.94 | E31: 33.94 | F31: 33.94 | G31: 33.94 | H31: 33.94 | I31: 33.94 | J31: 34.27 | K31: 34.62 | L31: 34.968 | M31: 35.32 | N31: 35.67 | O31: 36.03 | P31: 36.4 | Q31: 36.75 | R31: 37.12 | S31: 37.49 | T31: 37.87 | U31: 38.24 | V31: 38.63 | W31: 39.01 | X31: 39.4 | Y31: 39.8 | Z31: 40.2 | AA31: 40.6 | AB31: 41 | AC31: 41.41 | AD31: 41.83 | AE31: 42.25 | AF31: 42.67 | AG31: 43.09 | AH31: 43.53 | AI31: =AH31*1.01 -> 43.9653 | AJ31: =AI31*1.01 -> 44.404953 | AK31: =AJ31*1.01 -> 44.849003 | AL31: =AK31*1.01 -> 45.297493 | AM31: =AL31*1.01 -> 45.750467
A32: Cuba | B32: RESCKN
A33: Cuba | B33: RESHEL
A34: Cuba | B34: COMELC | C34: 28.86 | D34: 28.86 | E34: 28.86 | F34: 28.86 | G34: 28.86 | H34: 28.86 | I34: 28.86 | J34: 29.17 | K34: 29.49 | L34: 29.82 | M34: 30.15 | N34: 30.48 | O34: 30.81 | P34: 31.15 | Q34: 31.49 | R34: 31.84 | S34: 32.19 | T34: 32.55 | U34: 32.9 | V34: 33.27 | W34: 33.63 | X34: 34 | Y34: 34.38 | Z34: 34.75 | AA34: 35.14 | AB34: 35.52 | AC34: 35.91 | AD34: 36.31 | AE34: 36.71 | AF34: 37.11 | AG34: 37.52 | AH34: 37.93 | AI34: =AH34*1.01 -> 38.3093 | AJ34: =AI34*1.01 -> 38.692393 | AK34: =AJ34*1.01 -> 39.079317 | AL34: =AK34*1.01 -> 39.47011 | AM34: =AL34*1.01 -> 39.864811
A35: Cuba | B35: COMHEL
A36: Cuba | B36: LIGTHELEC
A37: Cuba | B37: CRUDEXP
A38: Cuba | B38: GASLIQ
A39: Cuba | B39: TRACAMDMY
A40: Cuba | B40: TRACARDMY
A41: Cuba | B41: TRAMCYDMY
A42: Cuba | B42: TRABUSDMY
A43: Cuba | B43: PRIVATEELC | C43: 1.69 | D43: 1.677 | E43: 1.988 | F43: 3 | G43: 3 | H43: 3 | I43: 3 | J43: 3.18 | K43: 3.25 | L43: 3.25 | M43: 3.28 | N43: 3.32 | O43: 3.35 | P43: 3.39 | Q43: 3.43 | R43: 3.47 | S43: 3.5 | T43: 3.54 | U43: 3.58 | V43: 3.62 | W43: 3.66 | X43: 3.7 | Y43: 3.74 | Z43: 3.789 | AA43: 3.83 | AB43: 3.87 | AC43: 3.915 | AD43: 3.95 | AE43: 4 | AF43: 4.04 | AG43: 4.09 | AH43: 4.14 | AI43: =AH43*1.01 -> 4.1814 | AJ43: =AI43*1.01 -> 4.223214 | AK43: =AJ43*1.01 -> 4.2654461 | AL43: =AK43*1.01 -> 4.3081006 | AM43: =AL43*1.01 -> 4.3511816
A44: Cuba | B44: AUXFUEL02
A45: Cuba | B45: AUXFUEL03
A46: Cuba | B46: AUXFUEL04
A47: Cuba | B47: AUXFUEL05 | C47: =(C43+C34+C31)/3.6/0.83/0.95 -> 21.771296 | D47: =(D43+D34+D31)/3.6/0.83/0.95 -> 22.714366 | E47: =(E43+E34+E31)/3.6/0.83/0.95 -> 22.823927 | F47: =(F43+F34+F31)/3.6/0.83/0.95 -> 23.180441 | G47: =(G43+G34+G31)/3.6/0.83/0.95 -> 23.180441 | H47: =(H43+H34+H31)/3.6/0.83/0.95 -> 23.180441 | I47: =(I43+I34+I31)/3.6/0.83/0.95 -> 23.180441 | J47: =(J43+J34+J31)/3.6/0.83/0.95 -> 23.469316 | ... AM47: =(AM43+AM34+AM31)/3.6/0.83/0.95 -> 31.693955
A48: Cuba | B48: AUXFUEL06 | C48: 21.771296 | D48: 22.714366 | E48: 22.823927 | F48: 23.180441 | G48: 23.180441 | H48: 23.180441 | I48: 23.180441 | J48: 23.469316 | K48: 23.730008 | L48: 23.968858 | M48: 24.219686 | N48: 24.473332 | O48: 24.726978 | P48: 24.991193 | Q48: 25.248362 | R48: 25.516099 | S48: 25.780314 | T48: 26.055098 | U48: 26.322835 | V48: 26.604664 | W48: 26.879448 | X48: 27.161277 | Y48: 27.450151 | Z48: 27.738674 | AA48: 28.031424 | AB48: 28.320299 | AC48: 28.617981 | AD48: 28.919186 | AE48: 29.225675 | AF48: 29.528641 | AG48: 29.838653 | AH48: 30.155711 | AI48: 30.457268 | AJ48: 30.76184 | AK48: 31.069459 | AL48: 31.380153 | AM48: 31.693955
A49: Cuba | B49: AUXFUEL07
A50: Cuba | B50: AUXFUEL08
A51: Cuba | B51: AUXFUEL09
A52: Cuba | B52: AUXFUEL10
A53: Cuba | B53: AUXFUEL11
A54: Cuba | B54: AUXFUEL12

Sheet SDP
A1: REGION | B1: FUEL | C1: TIMESLICE | D1: 2019 | E1: 2020 | F1: 2021 | G1: 2022 | H1: 2023 | I1: 2024 | J1: 2025 | K1: 2026 | L1: 2027 | M1: 2028 | N1: 2029 | O1: 2030 | P1: 2031 | Q1: 2032 | R1: 2033 | S1: 2034 | T1: 2035 | U1: 2036 | V1: 2037 | W1: 2038 | X1: 2039 | Y1: 2040 | Z1: 2041 | AA1: 2042 | AB1: 2043 | AC1: 2044 | AD1: 2045 | AE1: 2046 | AF1: 2047 | AG1: 2048 | AH1: 2049 | AI1: 2050 | AJ1: 2051 | AK1: 2052 | AL1: 2053 | AM1: 2054 | AN1: 2055
A2: Cuba | B2: CRUD | C2: 111
A3: Cuba | B3: CRUD | C3: 112
A4: Cuba | B4: CRUD | C4: 113
A5: Cuba | B5: CRUD | C5: 114
A6: Cuba | B6: CRUD | C6: 115
A7: Cuba | B7: CRUD | C7: 116
A8: Cuba | B8: CRUD | C8: 117
A9: Cuba | B9: CRUD | C9: 118
A10: Cuba | B10: CRUD | C10: 121
A11: Cuba | B11: CRUD | C11: 122
A12: Cuba | B12: CRUD | C12: 123
A13: Cuba | B13: CRUD | C13: 124
... A1857: Cuba | B1857: INDHEL | C1857: 428
A1858: Cuba | B1858: RESELC | C1858: 111 | D1858: 0.032 | E1858: 0.032 | F1858: 0.032 | G1858: 0.032 | H1858: 0.032 | I1858: 0.032 | J1858: 0.032 | K1858: 0.032 | L1858: 0.032 | M1858: 0.032 | N1858: 0.032 | O1858: 0.032 | P1858: 0.032 | Q1858: 0.032 | R1858: 0.032 | S1858: 0.032 | T1858: 0.032 | U1858: 0.032 | V1858: 0.032 | W1858: 0.032 | X1858: 0.032 | Y1858: 0.032 | Z1858: 0.032 | AA1858: 0.032 | AB1858: 0.032 | AC1858: 0.032 | AD1858: 0.032 | AE1858: 0.032 | AF1858: 0.032 | AG1858: 0.032 | AH1858: 0.032 | AI1858: 0.032 | AJ1858: 0.032 | AK1858: 0.032 | AL1858: 0.032 | AM1858: 0.032 | AN1858: 0.032
A1859: Cuba | B1859: RESELC | C1859: 112 | D1859: 0.025 | E1859: 0.025 | F1859: 0.025 | G1859: 0.025 | H1859: 0.025 | I1859: 0.025 | J1859: 0.025 | K1859: 0.025 | L1859: 0.025 | M1859: 0.025 | N1859: 0.025 | O1859: 0.025 | P1859: 0.025 | Q1859: 0.025 | R1859: 0.025 | S1859: 0.025 | T1859: 0.025 | U1859: 0.025 | V1859: 0.025 | W1859: 0.025 | X1859: 0.025 | Y1859: 0.025 | Z1859: 0.025 | AA1859: 0.025 | AB1859: 0.025 | AC1859: 0.025 | AD1859: 0.025 | AE1859: 0.025 | AF1859: 0.025 | AG1859: 0.025 | AH1859: 0.025 | AI1859: 0.025 | AJ1859: 0.025 | AK1859: 0.025 | AL1859: 0.025 | AM1859: 0.025 | AN1859: 0.025
A1860: Cuba | B1860: RESELC | C1860: 113 | D1860: 0.012 | E1860: 0.012 | F1860: 0.012 | G1860: 0.012 | H1860: 0.012 | I1860: 0.012 | J1860: 0.012 | K1860: 0.012 | L1860: 0.012 | M1860: 0.012 | N1860: 0.012 | O1860: 0.012 | P1860: 0.012 | Q1860: 0.012 | R1860: 0.012 | S1860: 0.012 | T1860: 0.012 | U1860: 0.012 | V1860: 0.012 | W1860: 0.012 | X1860: 0.012 | Y1860: 0.012 | Z1860: 0.012 | AA1860: 0.012 | AB1860: 0.012 | AC1860: 0.012 | AD1860: 0.012 | AE1860: 0.012 | AF1860: 0.012 | AG1860: 0.012 | AH1860: 0.012 | AI1860: 0.012 | AJ1860: 0.012 | AK1860: 0.012 | AL1860: 0.012 | AM1860: 0.012 | AN1860: 0.012
A1861: Cuba | B1861: RESELC | C1861: 114 | D1861: 0.02 | E1861: 0.02 | F1861: 0.02 | G1861: 0.02 | H1861: 0.02 | I1861: 0.02 | J1861: 0.02 | K1861: 0.02 | L1861: 0.02 | M1861: 0.02 | N1861: 0.02 | O1861: 0.02 | P1861: 0.02 | Q1861: 0.02 | R1861: 0.02 | S1861: 0.02 | T1861: 0.02 | U1861: 0.02 | V1861: 0.02 | W1861: 0.02 | X1861: 0.02 | Y1861: 0.02 | Z1861: 0.02 | AA1861: 0.02 | AB1861: 0.02 | AC1861: 0.02 | AD1861: 0.02 | AE1861: 0.02 | AF1861: 0.02 | AG1861: 0.02 | AH1861: 0.02 | AI1861: 0.02 | AJ1861: 0.02 | AK1861: 0.02 | AL1861: 0.02 | AM1861: 0.02 | AN1861: 0.02
A1862: Cuba | B1862: RESELC | C1862: 115 | D1862: 0.016 | E1862: 0.016 | F1862: 0.016 | G1862: 0.016 | H1862: 0.016 | I1862: 0.016 | J1862: 0.016 | K1862: 0.016 | L1862: 0.016 | M1862: 0.016 | N1862: 0.016 | O1862: 0.016 | P1862: 0.016 | Q1862: 0.016 | R1862: 0.016 | S1862: 0.016 | T1862: 0.016 | U1862: 0.016 | V1862: 0.016 | W1862: 0.016 | X1862: 0.016 | Y1862: 0.016 | Z1862: 0.016 | AA1862: 0.016 | AB1862: 0.016 | AC1862: 0.016 | AD1862: 0.016 | AE1862: 0.016 | AF1862: 0.016 | AG1862: 0.016 | AH1862: 0.016 | AI1862: 0.016 | AJ1862: 0.016 | AK1862: 0.016 | AL1862: 0.016 | AM1862: 0.016 | AN1862: 0.016
A1863: Cuba | B1863: RESELC | C1863: 116 | D1863: 0.021 | E1863: 0.021 | F1863: 0.021 | G1863: 0.021 | H1863: 0.021 | I1863: 0.021 | J1863: 0.021 | K1863: 0.021 | L1863: 0.021 | M1863: 0.021 | N1863: 0.021 | O1863: 0.021 | P1863: 0.021 | Q1863: 0.021 | R1863: 0.021 | S1863: 0.021 | T1863: 0.021 | U1863: 0.021 | V1863: 0.021 | W1863: 0.021 | X1863: 0.021 | Y1863: 0.021 | Z1863: 0.021 | AA1863: 0.021 | AB1863: 0.021 | AC1863: 0.021 | AD1863: 0.021 | AE1863: 0.021 | AF1863: 0.021 | AG1863: 0.021 | AH1863: 0.021 | AI1863: 0.021 | AJ1863: 0.021 | AK1863: 0.021 | AL1863: 0.021 | AM1863: 0.021 | AN1863: 0.021
A1864: Cuba | B1864: RESELC | C1864: 117 | D1864: 0.015 | E1864: 0.015 | F1864: 0.015 | G1864: 0.015 | H1864: 0.015 | I1864: 0.015 | J1864: 0.015 | K1864: 0.015 | L1864: 0.015 | M1864: 0.015 | N1864: 0.015 | O1864: 0.015 | P1864: 0.015 | Q1864: 0.015 | R1864: 0.015 | S1864: 0.015 | T1864: 0.015 | U1864: 0.015 | V1864: 0.015 | W1864: 0.015 | X1864: 0.015 | Y1864: 0.015 | Z1864: 0.015 | AA1864: 0.015 | AB1864: 0.015 | AC1864: 0.015 | AD1864: 0.015 | AE1864: 0.015 | AF1864: 0.015 | AG1864: 0.015 | AH1864: 0.015 | AI1864: 0.015 | AJ1864: 0.015 | AK1864: 0.015 | AL1864: 0.015 | AM1864: 0.015 | AN1864: 0.015
A1865: Cuba | B1865: RESELC | C1865: 118 | D1865: 0.017 | E1865: 0.017 | F1865: 0.017 | G1865: 0.017 | H1865: 0.017 | I1865: 0.017 | J1865: 0.017 | K1865: 0.017 | L1865: 0.017 | M1865: 0.017 | N1865: 0.017 | O1865: 0.017 | P1865: 0.017 | Q1865: 0.017 | R1865: 0.017 | S1865: 0.017 | T1865: 0.017 | U1865: 0.017 | V1865: 0.017 | W1865: 0.017 | X1865: 0.017 | Y1865: 0.017 | Z1865: 0.017 | AA1865: 0.017 | AB1865: 0.017 | AC1865: 0.017 | AD1865: 0.017 | AE1865: 0.017 | AF1865: 0.017 | AG1865: 0.017 | AH1865: 0.017 | AI1865: 0.017 | AJ1865: 0.017 | AK1865: 0.017 | AL1865: 0.017 | AM1865: 0.017 | AN1865: 0.017
A1866: Cuba | B1866: RESELC | C1866: 121 | D1866: 0.014 | E1866: 0.014 | F1866: 0.014 | G1866: 0.014 | H1866: 0.014 | I1866: 0.014 | J1866: 0.014 | K1866: 0.014 | L1866: 0.014 | M1866: 0.014 | N1866: 0.014 | O1866: 0.014 | P1866: 0.014 | Q1866: 0.014 | R1866: 0.014 | S1866: 0.014 | T1866: 0.014 | U1866: 0.014 | V1866: 0.014 | W1866: 0.014 | X1866: 0.014 | Y1866: 0.014 | Z1866: 0.014 | AA1866: 0.014 | AB1866: 0.014 | AC1866: 0.014 | AD1866: 0.014 | AE1866: 0.014 | AF1866: 0.014 | AG1866: 0.014 | AH1866: 0.014 | AI1866: 0.014 | AJ1866: 0.014 | AK1866: 0.014 | AL1866: 0.014 | AM1866: 0.014 | AN1866: 0.014
A1867: Cuba | B1867: RESELC | C1867: 122 | D1867: 0.011 | E1867: 0.011 | F1867: 0.011 | G1867: 0.011 | H1867: 0.011 | I1867: 0.011 | J1867: 0.011 | K1867: 0.011 | L1867: 0.011 | M1867: 0.011 | N1867: 0.011 | O1867: 0.011 | P1867: 0.011 | Q1867: 0.011 | R1867: 0.011 | S1867: 0.011 | T1867: 0.011 | U1867: 0.011 | V1867: 0.011 | W1867: 0.011 | X1867: 0.011 | Y1867: 0.011 | Z1867: 0.011 | AA1867: 0.011 | AB1867: 0.011 | AC1867: 0.011 | AD1867: 0.011 | AE1867: 0.011 | AF1867: 0.011 | AG1867: 0.011 | AH1867: 0.011 | AI1867: 0.011 | AJ1867: 0.011 | AK1867: 0.011 | AL1867: 0.011 | AM1867: 0.011 | AN1867: 0.011
A1868: Cuba | B1868: RESELC | C1868: 123 | D1868: 0.005 | E1868: 0.005 | F1868: 0.005 | G1868: 0.005 | H1868: 0.005 | I1868: 0.005 | J1868: 0.005 | K1868: 0.005 | L1868: 0.005 | M1868: 0.005 | N1868: 0.005 | O1868: 0.005 | P1868: 0.005 | Q1868: 0.005 | R1868: 0.005 | S1868: 0.005 | T1868: 0.005 | U1868: 0.005 | V1868: 0.005 | W1868: 0.005 | X1868: 0.005 | Y1868: 0.005 | Z1868: 0.005 | AA1868: 0.005 | AB1868: 0.005 | AC1868: 0.005 | AD1868: 0.005 | AE1868: 0.005 | AF1868: 0.005 | AG1868: 0.005 | AH1868: 0.005 | AI1868: 0.005 | AJ1868: 0.005 | AK1868: 0.005 | AL1868: 0.005 | AM1868: 0.005 | AN1868: 0.005
A1869: Cuba | B1869: RESELC | C1869: 124 | D1869: 0.009 | E1869: 0.009 | F1869: 0.009 | G1869: 0.009 | H1869: 0.009 | I1869: 0.009 | J1869: 0.009 | K1869: 0.009 | L1869: 0.009 | M1869: 0.009 | N1869: 0.009 | O1869: 0.009 | P1869: 0.009 | Q1869: 0.009 | R1869: 0.009 | S1869: 0.009 | T1869: 0.009 | U1869: 0.009 | V1869: 0.009 | W1869: 0.009 | X1869: 0.009 | Y1869: 0.009 | Z1869: 0.009 | AA1869: 0.009 | AB1869: 0.009 | AC1869: 0.009 | AD1869: 0.009 | AE1869: 0.009 | AF1869: 0.009 | AG1869: 0.009 | AH1869: 0.009 | AI1869: 0.009 | AJ1869: 0.009 | AK1869: 0.009 | AL1869: 0.009 | AM1869: 0.009 | AN1869: 0.009
... A1921: Cuba | B1921: RESELC | C1921: 428 | D1921: 0.007 | E1921: 0.007 | F1921: 0.007 | G1921: 0.007 | H1921: 0.007 | I1921: 0.007 | J1921: 0.007 | K1921: 0.007 | L1921: 0.007 | M1921: 0.007 | N1921: 0.007 | O1921: 0.007 | P1921: 0.007 | Q1921: 0.007 | R1921: 0.007 | S1921: 0.007 | T1921: 0.007 | U1921: 0.007 | V1921: 0.007 | W1921: 0.007 | X1921: 0.007 | Y1921: 0.007 | Z1921: 0.007 | AA1921: 0.007 | AB1921: 0.007 | AC1921: 0.007 | AD1921: 0.007 | AE1921: 0.007 | AF1921: 0.007 | AG1921: 0.007 | AH1921: 0.007 | AI1921: 0.007 | AJ1921: 0.007 | AK1921: 0.007 | AL1921: 0.007 | AM1921: 0.007 | AN1921: 0.007
A1922: Cuba | B1922: RESCKN | C1922: 111
A1923: Cuba | B1923: RESCKN | C1923: 112
A1924: Cuba | B1924: RESCKN | C1924: 113
A1925: Cuba | B1925: RESCKN | C1925: 114
A1926: Cuba | B1926: RESCKN | C1926: 115
A1927: Cuba | B1927: RESCKN | C1927: 116
A1928: Cuba | B1928: RESCKN | C1928: 117
A1929: Cuba | B1929: RESCKN | C1929: 118
A1930: Cuba | B1930: RESCKN | C1930: 121
A1931: Cuba | B1931: RESCKN | C1931: 122
A1932: Cuba | B1932: RESCKN | C1932: 123
A1933: Cuba | B1933: RESCKN | C1933: 124
... A2049: Cuba | B2049: RESHEL | C2049: 428
...

Sheet AAD
A1: REGION | B1: FUEL | C1: 2019 | D1: 2020 | E1: 2021 | F1: 2022 | G1: 2023 | H1: 2024 | I1: 2025 | J1: 2026 | K1: 2027 | L1: 2028 | M1: 2029 | N1: 2030 | O1: 2031 | P1: 2032 | Q1: 2033 | R1: 2034 | S1: 2035 | T1: 2036 | U1: 2037 | V1: 2038 | W1: 2039 | X1: 2040 | Y1: 2041 | Z1: 2042 | AA1: 2043 | AB1: 2044 | AC1: 2045 | AD1: 2046 | AE1: 2047 | AF1: 2048 | AG1: 2049 | AH1: 2050 | AI1: 2051 | AJ1: 2052 | AK1: 2053 | AL1: 2054 | AM1: 2055
A2: Cuba | B2: CRUD
A3: Cuba | B3: HFO01
A4: Cuba | B4: HFO02
A5: Cuba | B5: LFO
A6: Cuba | B6: DSL
A7: Cuba | B7: NG
A8: Cuba | B8: BIO01
A9: Cuba | B9: BIO02
A10: Cuba | B10: BIO03
A11: Cuba | B11: BIO04
A12: Cuba | B12: GASOLINE
A13: Cuba | B13: KEROSENE
... A54: Cuba | B54: AUXFUEL12

Sheet C2AU
A1: REGION | B1: IMPCRUDE | C1: MINCRUDE | D1: IMPHFO01 | E1: IMPHFO02 | F1: IMPLFO | G1: MINDIESEL | H1: IMPDIESEL | I1: IMPNG | J1: MINNG | K1: MINBIO1 | L1: MINBIO2 | M1: MINBIO3 | N1: MINBIO4 | O1: IMPBIO | P1: MINKEROSEN | Q1: IMPKEROSEN | R1: MINALCOHOL | S1: MINGASOLINE | T1: IMPGASOLINE | U1: MINSOL | V1: MINWIND | W1: MINHYDRO | X1: PWRCRUD001 | Y1: PWRCRUD002 | Z1: PWRCRUD003 | AA1: PWRCRUD004 | AB1: PWRCRUD008 | AC1: PWRCRUD005 | AD1: PWRCRUD006 | AE1: PWRCRUD007 | AF1: PWRCRUD009 | AG1: PWRNG01 | AH1: PWRNG02 | AI1: PWRGHFO2 | AJ1: PWRBIO01 | AK1: PWRBIO02 | AL1: PWRWND001 | AM1: PWRWND002 | AN1: PWRPV01 | AO1: PWRPV02 | AP1: PWRPV03 | AQ1: PWRCSP | AR1: PWRFO | AS1: PWRDSL | AT1: PWRHYD01 | AU1: PWRHYD02 | AV1: PWRTBATT01 | AW1: PWRTBATT02 | AX1: PWRTBATT03 | AY1: PWRTBATT04 | AZ1: TRANSMISSION | BA1: DISTRIBUTION | BB1: DEMRESIDEN | BC1: DEMPRIVATE | BD1: DEMCOMERC | BE1: DEMINDUST | BF1: DEMLIGTH | BG1: DEMTRAEVC | BH1: DEMTRACARELC | BI1: DEMTRAMCYELC | BJ1: DEMTRABUSELC | BK1: DEMTRACARGSL | BL1: DEMTRAMCYGSL | BM1: DEMTRABUSGSL | BN1: DEMTRABUSDSL | BO1: DEMTRAFREGHTCARELC | BP1: DEMTRAFREGHTCARDSL | BQ1: DEMTRACAR | BR1: DEMTRAMCY | BS1: DEMTRAAUX01 | BT1: DEMTRAAUX02 | BU1: DEMTRAAUX03 | BV1: DEMTRAAUX04 | BW1: RESIDENEFFGO | BX1: RESIDENEFFDP | BY1: DEMRESCKNBIO | BZ1: DEMRESCKNELC | CA1: DEMRESCKNNG | CB1: DEMRESCKNKS | CC1: DEMRESCKNALC | CD1: DEMRESCOOL | CE1: DEMRESAUX01 | CF1: DEMRESAUX02 | CG1: DEMRESAUX03 | CH1: DEMRESAUX04 | CI1: DEMCOMERCEFFGO | CJ1: DEMCOMERCEFFDP | CK1: DEMCOMERCHEBIO | CL1: DEMCOMERCHEEL | CM1: DEMCOMERCHEOIL | CN1: DEMCOMERCAUX01 | CO1: DEMCOMERCAUX02 | CP1: DEMCOMERCAUX03 | CQ1: DEMINDUSTEFFGO | CR1: DEMINDUSTEFFDP | CS1: DEMINDUSTHEBIO | CT1: DEMINDUSTHEEL | CU1: DEMINDUSTHEOIL | CV1: DEMINDUSTHENG | CW1: DEMINDUSTAUX01 | CX1: DEMINDUSTAUX02 | CY1: DEMINDUSTAUX03 | CZ1: GASLIQUED | DA1: EXPORT01 | DB1: EXPORT02 | DC1: EXPORT03 | DD1: IMPORT01 | DE1: IMPORT02 | DF1: IMPORT03 | DG1: VOLL_TECH | DH1: BSTOP02 | DI1: BSTOP03 | DJ1: BSTOP04 | DK1: BSTOP05 | DL1: BSTOP06 | DM1: BSTOP07 | DN1: BSTOP08 | DO1: BSTOP09 | DP1: BSTOP10 | DQ1: BSTOP11 | DR1: BSTOP12 | DS1: BSTOP13 | DT1: BSTOP14 | DU1: BSTOP15 | DV1: AUXTECH01 | DW1: AUXTECH02 | DX1: AUXTECH03 | DY1: AUXTECH04 | DZ1: AUXTECH05 | EA1: AUXTECH06 | EB1: AUXTECH07 | EC1: AUXTECH08 | ED1: AUXTECH09 | EE1: AUXTECH10
A2: Cuba | X2: 31.536 | Y2: 31.536 | Z2: 31.536 | AA2: 31.536 | AB2: 31.536 | AC2: 31.536 | AD2: 31.536 | AE2: 31.536 | AF2: 31.536 | AG2: 31.536 | AH2: 31.536 | AI2: 31.536 | AJ2: 31.536 | AK2: 31.536 | AL2: 31.536 | AM2: 31.536 | AN2: 31.536 | AO2: 31.536 | AP2: 31.536 | AQ2: 31.536 | AR2: 31.536 | AS2: 31.536 | AT2: 31.536 | AU2: 31.536 | AV2: 31.536 | AW2: 31.536 | AX2: 31.536 | AY2: 31.536 | AZ2: 31.536 | BA2: 31.536 | DG2: 31.536 | DH2: 31.536 | DI2: 31.536 | DJ2: 31.536 | DV2: 31.536

Sheet CF
A1: REGION | B1: TECHNOLOGY | C1: TIMESLICE | D1: 2019 | E1: 2020 | F1: 2021 | G1: 2022 | H1: 2023 | I1: 2024 | J1: 2025 | K1: 2026 | L1: 2027 | M1: 2028 | N1: 2029 | O1: 2030 | P1: 2031 | Q1: 2032 | R1: 2033 | S1: 2034 | T1: 2035 | U1: 2036 | V1: 2037 | W1: 2038 | X1: 2039 | Y1: 2040 | Z1: 2041 | AA1: 2042 | AB1: 2043 | AC1: 2044 | AD1: 2045 | AE1: 2046 | AF1: 2047 | AG1: 2048 | AH1: 2049 | AI1: 2050 | AJ1: 2051 | AK1: 2052 | AL1: 2053 | AM1: 2054 | AN1: 2055
A2: Cuba | B2: IMPCRUDE | C2: 111
A3: Cuba | B3: IMPCRUDE | C3: 112
A4: Cuba | B4: IMPCRUDE | C4: 113
A5: Cuba | B5: IMPCRUDE | C5: 114
A6: Cuba | B6: IMPCRUDE | C6: 115
A7: Cuba | B7: IMPCRUDE | C7: 116
A8: Cuba | B8: IMPCRUDE | C8: 117
A9: Cuba | B9: IMPCRUDE | C9: 118
A10: Cuba | B10: IMPCRUDE | C10: 121
A11: Cuba | B11: IMPCRUDE | C11: 122
A12: Cuba | B12: IMPCRUDE | C12: 123
A13: Cuba | B13: IMPCRUDE | C13: 124
... A2273: Cuba | B2273: PWRBIO02 | C2273: 228
A2274: Cuba | B2274: PWRBIO02 | C2274: 311 | D2274: 0 | E2274: 0 | F2274: 0 | G2274: 0 | H2274: 0 | I2274: 0 | J2274: 0 | K2274: 0 | L2274: 0 | M2274: 0 | N2274: 0 | O2274: 0 | P2274: 0 | Q2274: 0 | R2274: 0 | S2274: 0 | T2274: 0 | U2274: 0 | V2274: 0 | W2274: 0 | X2274: 0 | Y2274: 0 | Z2274: 0 | AA2274: 0 | AB2274: 0 | AC2274: 0 | AD2274: 0 | AE2274: 0 | AF2274: 0 | AG2274: 0 | AH2274: 0 | AI2274: 0 | AJ2274: 0 | AK2274: 0 | AL2274: 0 | AM2274: 0 | AN2274: 0
A2275: Cuba | B2275: PWRBIO02 | C2275: 312 | D2275: 0 | E2275: 0 | F2275: 0 | G2275: 0 | H2275: 0 | I2275: 0 | J2275: 0 | K2275: 0 | L2275: 0 | M2275: 0 | N2275: 0 | O2275: 0 | P2275: 0 | Q2275: 0 | R2275: 0 | S2275: 0 | T2275: 0 | U2275: 0 | V2275: 0 | W2275: 0 | X2275: 0 | Y2275: 0 | Z2275: 0 | AA2275: 0 | AB2275: 0 | AC2275: 0 | AD2275: 0 | AE2275: 0 | AF2275: 0 | AG2275: 0 | AH2275: 0 | AI2275: 0 | AJ2275: 0 | AK2275: 0 | AL2275: 0 | AM2275: 0 | AN2275: 0
A2276: Cuba | B2276: PWRBIO02 | C2276: 313 | D2276: 0 | E2276: 0 | F2276: 0 | G2276: 0 | H2276: 0 | I2276: 0 | J2276: 0 | K2276: 0 | L2276: 0 | M2276: 0 | N2276: 0 | O2276: 0 | P2276: 0 | Q2276: 0 | R2276: 0 | S2276: 0 | T2276: 0 | U2276: 0 | V2276: 0 | W2276: 0 | X2276: 0 | Y2276: 0 | Z2276: 0 | AA2276: 0 | AB2276: 0 | AC2276: 0 | AD2276: 0 | AE2276: 0 | AF2276: 0 | AG2276: 0 | AH2276: 0 | AI2276: 0 | AJ2276: 0 | AK2276: 0 | AL2276: 0 | AM2276: 0 | AN2276: 0
A2277: Cuba | B2277: PWRBIO02 | C2277: 314 | D2277: 0 | E2277: 0 | F2277: 0 | G2277: 0 | H2277: 0 | I2277: 0 | J2277: 0 | K2277: 0 | L2277: 0 | M2277: 0 | N2277: 0 | O2277: 0 | P2277: 0 | Q2277: 0 | R2277: 0 | S2277: 0 | T2277: 0 | U2277: 0 | V2277: 0 | W2277: 0 | X2277: 0 | Y2277: 0 | Z2277: 0 | AA2277: 0 | AB2277: 0 | AC2277: 0 | AD2277: 0 | AE2277: 0 | AF2277: 0 | AG2277: 0 | AH2277: 0 | AI2277: 0 | AJ2277: 0 | AK2277: 0 | AL2277: 0 | AM2277: 0 | AN2277: 0
A2278: Cuba | B2278: PWRBIO02 | C2278: 315 | D2278: 0 | E2278: 0 | F2278: 0 | G2278: 0 | H2278: 0 | I2278: 0 | J2278: 0 | K2278: 0 | L2278: 0 | M2278: 0 | N2278: 0 | O2278: 0 | P2278: 0 | Q2278: 0 | R2278: 0 | S2278: 0 | T2278: 0 | U2278: 0 | V2278: 0 | W2278: 0 | X2278: 0 | Y2278: 0 | Z2278: 0 | AA2278: 0 | AB2278: 0 | AC2278: 0 | AD2278: 0 | AE2278: 0 | AF2278: 0 | AG2278: 0 | AH2278: 0 | AI2278: 0 | AJ2278: 0 | AK2278: 0 | AL2278: 0 | AM2278: 0 | AN2278: 0
A2279: Cuba | B2279: PWRBIO02 | C2279: 316 | D2279: 0 | E2279: 0 | F2279: 0 | G2279: 0 | H2279: 0 | I2279: 0 | J2279: 0 | K2279: 0 | L2279: 0 | M2279: 0 | N2279: 0 | O2279: 0 | P2279: 0 | Q2279: 0 | R2279: 0 | S2279: 0 | T2279: 0 | U2279: 0 | V2279: 0 | W2279: 0 | X2279: 0 | Y2279: 0 | Z2279: 0 | AA2279: 0 | AB2279: 0 | AC2279: 0 | AD2279: 0 | AE2279: 0 | AF2279: 0 | AG2279: 0 | AH2279: 0 | AI2279: 0 | AJ2279: 0 | AK2279: 0 | AL2279: 0 | AM2279: 0 | AN2279: 0
A2280: Cuba | B2280: PWRBIO02 | C2280: 317 | D2280: 0 | E2280: 0 | F2280: 0 | G2280: 0 | H2280: 0 | I2280: 0 | J2280: 0 | K2280: 0 | L2280: 0 | M2280: 0 | N2280: 0 | O2280: 0 | P2280: 0 | Q2280: 0 | R2280: 0 | S2280: 0 | T2280: 0 | U2280: 0 | V2280: 0 | W2280: 0 | X2280: 0 | Y2280: 0 | Z2280: 0 | AA2280: 0 | AB2280: 0 | AC2280: 0 | AD2280: 0 | AE2280: 0 | AF2280: 0 | AG2280: 0 | AH2280: 0 | AI2280: 0 | AJ2280: 0 | AK2280: 0 | AL2280: 0 | AM2280: 0 | AN2280: 0
A2281: Cuba | B2281: PWRBIO02 | C2281: 318 | D2281: 0 | E2281: 0 | F2281: 0 | G2281: 0 | H2281: 0 | I2281: 0 | J2281: 0 | K2281: 0 | L2281: 0 | M2281: 0 | N2281: 0 | O2281: 0 | P2281: 0 | Q2281: 0 | R2281: 0 | S2281: 0 | T2281: 0 | U2281: 0 | V2281: 0 | W2281: 0 | X2281: 0 | Y2281: 0 | Z2281: 0 | AA2281: 0 | AB2281: 0 | AC2281: 0 | AD2281: 0 | AE2281: 0 | AF2281: 0 | AG2281: 0 | AH2281: 0 | AI2281: 0 | AJ2281: 0 | AK2281: 0 | AL2281: 0 | AM2281: 0 | AN2281: 0
A2282: Cuba | B2282: PWRBIO02 | C2282: 321 | D2282: 0 | E2282: 0 | F2282: 0 | G2282: 0 | H2282: 0 | I2282: 0 | J2282: 0 | K2282: 0 | L2282: 0 | M2282: 0 | N2282: 0 | O2282: 0 | P2282: 0 | Q2282: 0 | R2282: 0 | S2282: 0 | T2282: 0 | U2282: 0 | V2282: 0 | W2282: 0 | X2282: 0 | Y2282: 0 | Z2282: 0 | AA2282: 0 | AB2282: 0 | AC2282: 0 | AD2282: 0 | AE2282: 0 | AF2282: 0 | AG2282: 0 | AH2282: 0 | AI2282: 0 | AJ2282: 0 | AK2282: 0 | AL2282: 0 | AM2282: 0 | AN2282: 0
A2283: Cuba | B2283: PWRBIO02 | C2283: 322 | D2283: 0 | E2283: 0 | F2283: 0 | G2283: 0 | H2283: 0 | I2283: 0 | J2283: 0 | K2283: 0 | L2283: 0 | M2283: 0 | N2283: 0 | O2283: 0 | P2283: 0 | Q2283: 0 | R2283: 0 | S2283: 0 | T2283: 0 | U2283: 0 | V2283: 0 | W2283: 0 | X2283: 0 | Y2283: 0 | Z2283: 0 | AA2283: 0 | AB2283: 0 | AC2283: 0 | AD2283: 0 | AE2283: 0 | AF2283: 0 | AG2283: 0 | AH2283: 0 | AI2283: 0 | AJ2283: 0 | AK2283: 0 | AL2283: 0 | AM2283: 0 | AN2283: 0
A2284: Cuba | B2284: PWRBIO02 | C2284: 323 | D2284: 0 | E2284: 0 | F2284: 0 | G2284: 0 | H2284: 0 | I2284: 0 | J2284: 0 | K2284: 0 | L2284: 0 | M2284: 0 | N2284: 0 | O2284: 0 | P2284: 0 | Q2284: 0 | R2284: 0 | S2284: 0 | T2284: 0 | U2284: 0 | V2284: 0 | W2284: 0 | X2284: 0 | Y2284: 0 | Z2284: 0 | AA2284: 0 | AB2284: 0 | AC2284: 0 | AD2284: 0 | AE2284: 0 | AF2284: 0 | AG2284: 0 | AH2284: 0 | AI2284: 0 | AJ2284: 0 | AK2284: 0 | AL2284: 0 | AM2284: 0 | AN2284: 0
A2285: Cuba | B2285: PWRBIO02 | C2285: 324 | D2285: 0 | E2285: 0 | F2285: 0 | G2285: 0 | H2285: 0 | I2285: 0 | J2285: 0 | K2285: 0 | L2285: 0 | M2285: 0 | N2285: 0 | O2285: 0 | P2285: 0 | Q2285: 0 | R2285: 0 | S2285: 0 | T2285: 0 | U2285: 0 | V2285: 0 | W2285: 0 | X2285: 0 | Y2285: 0 | Z2285: 0 | AA2285: 0 | AB2285: 0 | AC2285: 0 | AD2285: 0 | AE2285: 0 | AF2285: 0 | AG2285: 0 | AH2285: 0 | AI2285: 0 | AJ2285: 0 | AK2285: 0 | AL2285: 0 | AM2285: 0 | AN2285: 0
... A2369: Cuba | B2369: PWRWND001 | C2369: 428 | D2369: 0.267 | E2369: 0.267 | F2369: 0.267 | G2369: 0.267 | H2369: 0.267 | I2369: 0.267 | J2369: 0.267 | K2369: 0.267 | L2369: 0.267 | M2369: 0.267 | N2369: 0.267 | O2369: 0.267 | P2369: 0.267 | Q2369: 0.267 | R2369: 0.267 | S2369: 0.267 | T2369: 0.267 | U2369: 0.267 | V2369: 0.267 | W2369: 0.267 | X2369: 0.267 | Y2369: 0.267 | Z2369: 0.267 | AA2369: 0.267 | AB2369: 0.267 | AC2369: 0.267 | AD2369: 0.267 | AE2369: 0.267 | AF2369: 0.267 | AG2369: 0.267 | AH2369: 0.267 | AI2369: 0.267 | AJ2369: 0.267 | AK2369: 0.267 | AL2369: 0.267 | AM2369: 0.267 | AN2369: 0.267
A2370: Cuba | B2370: PWRWND002 | C2370: 111
A2371: Cuba | B2371: PWRWND002 | C2371: 112
A2372: Cuba | B2372: PWRWND002 | C2372: 113
A2373: Cuba | B2373: PWRWND002 | C2373: 114
A2374: Cuba | B2374: PWRWND002 | C2374: 115
A2375: Cuba | B2375: PWRWND002 | C2375: 116
A2376: Cuba | B2376: PWRWND002 | C2376: 117
A2377: Cuba | B2377: PWRWND002 | C2377: 118
A2378: Cuba | B2378: PWRWND002 | C2378: 121
A2379: Cuba | B2379: PWRWND002 | C2379: 122
A2380: Cuba | B2380: PWRWND002 | C2380: 123
A2381: Cuba | B2381: PWRWND002 | C2381: 124
... A2433: Cuba | B2433: PWRWND002 | C2433: 428
...

Sheet AF
A1: REGION | B1: TECHNOLOGY | C1: 2019 | D1: 2020 | E1: 2021 | F1: 2022 | G1: 2023 | H1: 2024 | I1: 2025 | J1: 2026 | K1: 2027 | L1: 2028 | M1: 2029 | N1: 2030 | O1: 2031 | P1: 2032 | Q1: 2033 | R1: 2034 | S1: 2035 | T1: 2036 | U1: 2037 | V1: 2038 | W1: 2039 | X1: 2040 | Y1: 2041 | Z1: 2042 | AA1: 2043 | AB1: 2044 | AC1: 2045 | AD1: 2046 | AE1: 2047 | AF1: 2048 | AG1: 2049 | AH1: 2050 | AI1: 2051 | AJ1: 2052 | AK1: 2053 | AL1: 2054 | AM1: 2055
A2: Cuba | B2: IMPCRUDE
A3: Cuba | B3: MINCRUDE
A4: Cuba | B4: IMPHFO01
A5: Cuba | B5: IMPHFO02
A6: Cuba | B6: IMPLFO
A7: Cuba | B7: MINDIESEL
A8: Cuba | B8: IMPDIESEL
A9: Cuba | B9: IMPNG
A10: Cuba | B10: MINNG
A11: Cuba | B11: MINBIO1
A12: Cuba | B12: MINBIO2
A13: Cuba | B13: MINBIO3
... A23: Cuba | B23: MINHYDRO
A24: Cuba | B24: PWRCRUD001 | C24: 0.73 | D24: 0.73 | E24: 0.73 | F24: 0.73 | G24: 0.73 | H24: 0.73 | I24: 0.95 | J24: =I24 -> 0.95 | K24: =J24 -> 0.95 | L24: =K24 -> 0.95 | M24: =L24 -> 0.95 | N24: =M24 -> 0.95 | O24: =N24 -> 0.95 | P24: =O24 -> 0.95 | Q24: 0.95 | R24: =Q24 -> 0.95 | S24: 0.95 | T24: =S24 -> 0.95 | U24: 0.95 | V24: =U24 -> 0.95 | W24: 0.95 | X24: =W24 -> 0.95 | Y24: 0.95 | Z24: =Y24 -> 0.95 | AA24: 0.95 | AB24: =AA24 -> 0.95 | AC24: 0.95 | AD24: =AC24 -> 0.95 | AE24: 0.95 | AF24: =AE24 -> 0.95 | AG24: 0.95 | AH24: =AG24 -> 0.95 | AI24: =AH24 -> 0.95 | AJ24: =AI24 -> 0.95 | AK24: =AJ24 -> 0.95 | AL24: =AK24 -> 0.95 | AM24: =AL24 -> 0.95
A25: Cuba | B25: PWRCRUD002 | C25: 0.53 | D25: 0.53 | E25: 0.53 | F25: 0.53 | G25: 0.53 | H25: 0.53 | I25: 0.53 | J25: 0.53 | K25: 0.95 | L25: =I24 -> 0.95 | M25: =J24 -> 0.95 | N25: =K24 -> 0.95 | O25: =L24 -> 0.95 | P25: =M24 -> 0.95 | Q25: 0.95 | R25: =Q25 -> 0.95 | S25: 0.95 | T25: =S25 -> 0.95 | U25: 0.95 | V25: =U25 -> 0.95 | W25: 0.95 | X25: =W25 -> 0.95 | Y25: 0.95 | Z25: =Y25 -> 0.95 | AA25: 0.95 | AB25: =AA25 -> 0.95 | AC25: 0.95 | AD25: =AC25 -> 0.95 | AE25: 0.95 | AF25: =AE25 -> 0.95 | AG25: 0.95 | AH25: =AG25 -> 0.95 | AI25: =AH25 -> 0.95 | AJ25: =AI25 -> 0.95 | AK25: =AJ25 -> 0.95 | AL25: =AK25 -> 0.95 | AM25: =AL25 -> 0.95
A26: Cuba | B26: PWRCRUD003 | C26: 0.68 | D26: 0.68 | E26: 0.68 | F26: 0.68 | G26: 0.68 | H26: 0.68 | I26: 0.68 | J26: 0.68 | K26: =I24 -> 0.95 | L26: =J24 -> 0.95 | M26: =K24 -> 0.95 | N26: =L24 -> 0.95 | O26: =M24 -> 0.95 | P26: =N24 -> 0.95 | Q26: 0.95 | R26: =Q26 -> 0.95 | S26: 0.95 | T26: =S26 -> 0.95 | U26: 0.95 | V26: =U26 -> 0.95 | W26: 0.95 | X26: =W26 -> 0.95 | Y26: 0.95 | Z26: =Y26 -> 0.95 | AA26: 0.95 | AB26: =AA26 -> 0.95 | AC26: 0.95 | AD26: =AC26 -> 0.95 | AE26: 0.95 | AF26: =AE26 -> 0.95 | AG26: 0.95 | AH26: =AG26 -> 0.95 | AI26: =AH26 -> 0.95 | AJ26: =AI26 -> 0.95 | AK26: =AJ26 -> 0.95 | AL26: =AK26 -> 0.95 | AM26: =AL26 -> 0.95
A27: Cuba | B27: PWRCRUD004 | C27: 0.73 | D27: 0.73 | E27: 0.73 | F27: 0.73 | G27: 0.73 | H27: 0.73 | I27: 0.73 | J27: 0.73 | K27: 0.73 | L27: =I24 -> 0.95 | M27: =J24 -> 0.95 | N27: =K24 -> 0.95 | O27: =L24 -> 0.95 | P27: =M24 -> 0.95 | Q27: 0.95 | R27: =Q27 -> 0.95 | S27: 0.95 | T27: =S27 -> 0.95 | U27: 0.95 | V27: =U27 -> 0.95 | W27: 0.95 | X27: =W27 -> 0.95 | Y27: 0.95 | Z27: =Y27 -> 0.95 | AA27: 0.95 | AB27: =AA27 -> 0.95 | AC27: 0.95 | AD27: =AC27 -> 0.95 | AE27: 0.95 | AF27: =AE27 -> 0.95 | AG27: 0.95 | AH27: =AG27 -> 0.95 | AI27: =AH27 -> 0.95 | AJ27: =AI27 -> 0.95 | AK27: =AJ27 -> 0.95 | AL27: =AK27 -> 0.95 | AM27: =AL27 -> 0.95
A28: Cuba | B28: PWRCRUD008 | C28: 0.75 | D28: 0.75 | E28: 0.75 | F28: 0.75 | G28: 0.75 | H28: 0.75 | I28: 0.75 | J28: 0.75 | K28: 0.75 | L28: 0.75 | M28: =L27 -> 0.95 | N28: =M27 -> 0.95 | O28: =N27 -> 0.95 | P28: =O27 -> 0.95 | Q28: 0.95 | R28: =Q28 -> 0.95 | S28: 0.95 | T28: =S28 -> 0.95 | U28: 0.95 | V28: =U28 -> 0.95 | W28: 0.95 | X28: =W28 -> 0.95 | Y28: 0.95 | Z28: =Y28 -> 0.95 | AA28: 0.95 | AB28: =AA28 -> 0.95 | AC28: 0.95 | AD28: =AC28 -> 0.95 | AE28: 0.95 | AF28: =AE28 -> 0.95 | AG28: 0.95 | AH28: =AG28 -> 0.95 | AI28: =AH28 -> 0.95 | AJ28: =AI28 -> 0.95 | AK28: =AJ28 -> 0.95 | AL28: =AK28 -> 0.95 | AM28: =AL28 -> 0.95
A29: Cuba | B29: PWRCRUD005 | C29: 0.66 | D29: 0.66 | E29: 0.66 | F29: 0.66 | G29: 0.66 | H29: 0.66 | I29: 0.66 | J29: 0.66 | K29: 0.66 | L29: 0.66 | M29: 0.66 | N29: =M28 -> 0.95 | O29: =N28 -> 0.95 | P29: =O28 -> 0.95 | Q29: 0.95 | R29: =Q29 -> 0.95 | S29: 0.95 | T29: =S29 -> 0.95 | U29: 0.95 | V29: =U29 -> 0.95 | W29: 0.95 | X29: =W29 -> 0.95 | Y29: 0.95 | Z29: =Y29 -> 0.95 | AA29: 0.95 | AB29: =AA29 -> 0.95 | AC29: 0.95 | AD29: =AC29 -> 0.95 | AE29: 0.95 | AF29: =AE29 -> 0.95 | AG29: 0.95 | AH29: =AG29 -> 0.95 | AI29: =AH29 -> 0.95 | AJ29: =AI29 -> 0.95 | AK29: =AJ29 -> 0.95 | AL29: =AK29 -> 0.95 | AM29: =AL29 -> 0.95
A30: Cuba | B30: PWRCRUD006 | C30: 0.37 | D30: 0.37 | E30: 0.37 | F30: 0.37 | G30: 0.37 | H30: 0.37 | I30: 0.37 | J30: 0.37 | K30: 0.37 | L30: 0.37 | M30: 0.37 | N30: 0.37 | O30: =N29 -> 0.95 | P30: =O29 -> 0.95 | Q30: 0.95 | R30: =Q30 -> 0.95 | S30: 0.95 | T30: =S30 -> 0.95 | U30: 0.95 | V30: =U30 -> 0.95 | W30: 0.95 | X30: =W30 -> 0.95 | Y30: 0.95 | Z30: =Y30 -> 0.95 | AA30: 0.95 | AB30: =AA30 -> 0.95 | AC30: 0.95 | AD30: =AC30 -> 0.95 | AE30: 0.95 | AF30: =AE30 -> 0.95 | AG30: 0.95 | AH30: =AG30 -> 0.95 | AI30: =AH30 -> 0.95 | AJ30: =AI30 -> 0.95 | AK30: =AJ30 -> 0.95 | AL30: =AK30 -> 0.95 | AM30: =AL30 -> 0.95
A31: Cuba | B31: PWRCRUD007 | C31: 0.48 | D31: 0.48 | E31: 0.48 | F31: 0.48 | G31: 0.48 | H31: 0.48 | I31: 0.48 | J31: 0.48 | K31: 0.48 | L31: 0.48 | M31: 0.48 | N31: 0.48 | O31: 0.48 | P31: =O30 -> 0.95 | Q31: 0.95 | R31: =Q31 -> 0.95 | S31: 0.95 | T31: =S31 -> 0.95 | U31: 0.95 | V31: =U31 -> 0.95 | W31: 0.95 | X31: =W31 -> 0.95 | Y31: 0.95 | Z31: =Y31 -> 0.95 | AA31: 0.95 | AB31: =AA31 -> 0.95 | AC31: 0.95 | AD31: =AC31 -> 0.95 | AE31: 0.95 | AF31: =AE31 -> 0.95 | AG31: 0.95 | AH31: =AG31 -> 0.95 | AI31: =AH31 -> 0.95 | AJ31: =AI31 -> 0.95 | AK31: =AJ31 -> 0.95 | AL31: =AK31 -> 0.95 | AM31: =AL31 -> 0.95
A32: Cuba | B32: PWRCRUD009 | C32: 0.95 | D32: 0.95 | E32: 0.95 | F32: 0.95 | G32: 0.95 | H32: 0.95 | I32: 0.95 | J32: =I32 -> 0.95 | K32: 0.95 | L32: =K32 -> 0.95 | M32: 0.95 | N32: =M32 -> 0.95 | O32: 0.95 | P32: =O32 -> 0.95 | Q32: 0.95 | R32: =Q32 -> 0.95 | S32: 0.95 | T32: =S32 -> 0.95 | U32: 0.95 | V32: =U32 -> 0.95 | W32: 0.95 | X32: =W32 -> 0.95 | Y32: 0.95 | Z32: =Y32 -> 0.95 | AA32: 0.95 | AB32: =AA32 -> 0.95 | AC32: 0.95 | AD32: =AC32 -> 0.95 | AE32: 0.95 | AF32: =AE32 -> 0.95 | AG32: 0.95 | AH32: =AG32 -> 0.95 | AI32: =AH32 -> 0.95 | AJ32: =AI32 -> 0.95 | AK32: =AJ32 -> 0.95 | AL32: =AK32 -> 0.95 | AM32: =AL32 -> 0.95
A33: Cuba | B33: PWRNG01 | C33: 0.68 | D33: 0.68 | E33: 0.68 | F33: 0.68 | G33: 0.68 | H33: 0.68 | I33: 0.68 | J33: =I33 -> 0.68 | K33: =J33 -> 0.68 | L33: =K33 -> 0.68 | M33: =L33 -> 0.68 | N33: =M33 -> 0.68 | O33: =N33 -> 0.68 | P33: =O33 -> 0.68 | Q33: =P33 -> 0.68 | ... AM33: =AL33 -> 0.68
A34: Cuba | B34: PWRNG02 | C34: 0.75 | D34: 0.75 | E34: 0.75 | F34: 0.75 | G34: 0.75 | H34: 0.75 | I34: 0.75 | J34: =I34 -> 0.75 | K34: =J34 -> 0.75 | L34: =K34 -> 0.75 | M34: =L34 -> 0.75 | N34: =M34 -> 0.75 | O34: =N34 -> 0.75 | P34: =O34 -> 0.75 | Q34: =P34 -> 0.75 | ... AM34: =AL34 -> 0.75
A35: Cuba | B35: PWRGHFO2 | C35: 0.75 | D35: 0.75 | E35: 0.75 | F35: 0.75 | G35: 0.75 | H35: 0.75 | I35: 0.75 | J35: =I35 -> 0.75 | K35: =J35 -> 0.75 | L35: =K35 -> 0.75 | M35: =L35 -> 0.75 | N35: =M35 -> 0.75 | O35: =N35 -> 0.75 | P35: =O35 -> 0.75 | Q35: =P35 -> 0.75 | ... AM35: =AL35 -> 0.75
A36: Cuba | B36: PWRBIO01 | C36: 0.85 | D36: 0.85 | E36: 0.85 | F36: 0.85 | G36: 0.85 | H36: 0.85 | I36: 0.85 | J36: =I36 -> 0.85 | K36: =J36 -> 0.85 | L36: =K36 -> 0.85 | M36: =L36 -> 0.85 | N36: =M36 -> 0.85 | O36: =N36 -> 0.85 | P36: =O36 -> 0.85 | Q36: =P36 -> 0.85 | ... AM36: =AL36 -> 0.85
A37: Cuba | B37: PWRBIO02 | C37: 0.35 | D37: 0.35 | E37: 0.35 | F37: 0.35 | G37: 0.35 | H37: 0.35 | I37: 0.35 | J37: 0.35 | K37: 0.35 | L37: 0.35 | M37: 0.35 | N37: 0.35 | O37: 0.35 | P37: 0.35 | Q37: 0.35 | R37: 0.35 | S37: 0.35 | T37: 0.35 | U37: 0.35 | V37: 0.35 | W37: 0.35 | X37: 0.35 | Y37: 0.35 | Z37: 0.35 | AA37: 0.35 | AB37: 0.35 | AC37: 0.35 | AD37: 0.35 | AE37: 0.35 | AF37: 0.35 | AG37: 0.35 | AH37: 0.35 | AI37: 0.35 | AJ37: 0.35 | AK37: 0.35 | AL37: 0.35 | AM37: 0.35
A38: Cuba | B38: PWRWND001
A39: Cuba | B39: PWRWND002
A40: Cuba | B40: PWRPV01
A41: Cuba | B41: PWRPV02
A42: Cuba | B42: PWRPV03
A43: Cuba | B43: PWRCSP
A44: Cuba | B44: PWRFO | C44: 0.35 | D44: 0.33 | E44: 0.5 | F44: 0.24 | G44: 0.18 | H44: 0.13 | I44: 0.35 | J44: 0.35 | K44: 0.95 | L44: 0.95 | M44: 0.95 | N44: 0.95 | O44: 0.95 | P44: 0.95 | Q44: 0.95 | R44: 0.95 | S44: 0.95 | T44: 0.95 | U44: 0.95 | V44: 0.95 | W44: 0.95 | X44: 0.95 | Y44: 0.95 | Z44: 0.95 | AA44: 0.95 | AB44: 0.95 | AC44: 0.95 | AD44: 0.95 | AE44: 0.95 | AF44: 0.95 | AG44: 0.95 | AH44: 0.95 | AI44: 0.95 | AJ44: 0.95 | AK44: 0.95 | AL44: 0.95 | AM44: 0.95
A45: Cuba | B45: PWRDSL | C45: 0.15 | D45: 0.12 | E45: 0.13 | F45: 0.13 | G45: 0.12 | H45: 0.098 | I45: 0.6 | J45: 0.6 | K45: 0.6 | L45: 0.6 | M45: 0.6 | N45: 0.6 | O45: 0.6 | P45: 0.6 | Q45: 0.6 | R45: 0.6 | S45: 0.6 | T45: 0.6 | U45: 0.6 | V45: 0.6 | W45: 0.6 | X45: 0.6 | Y45: 0.6 | Z45: 0.6 | AA45: 0.6 | AB45: 0.6 | AC45: 0.6 | AD45: 0.6 | AE45: 0.6 | AF45: 0.6 | AG45: 0.6 | AH45: 0.6 | AI45: 0.6 | AJ45: 0.6 | AK45: 0.6 | AL45: 0.6 | AM45: 0.6
A46: Cuba | B46: PWRHYD01 | C46: 0.85 | D46: 0.85 | E46: 0.85 | F46: 0.85 | G46: 0.85 | H46: 0.85 | I46: 0.85 | J46: =I46 -> 0.85 | K46: =J46 -> 0.85 | L46: =K46 -> 0.85 | M46: =L46 -> 0.85 | N46: =M46 -> 0.85 | O46: =N46 -> 0.85 | P46: =O46 -> 0.85 | Q46: =P46 -> 0.85 | ... AM46: =AL46 -> 0.85
A47: Cuba | B47: PWRHYD02 | C47: 0.5 | D47: 0.5 | E47: 0.5 | F47: 0.5 | G47: 0.5 | H47: 0.5 | I47: 0.5 | J47: 0.5 | K47: 0.5 | L47: 0.5 | M47: 0.5 | N47: 0.5 | O47: 0.5 | P47: 0.5 | Q47: 0.5 | R47: 0.5 | S47: 0.5 | T47: 0.5 | U47: 0.5 | V47: 0.5 | W47: 0.5 | X47: 0.5 | Y47: 0.5 | Z47: 0.5 | AA47: 0.5 | AB47: 0.5 | AC47: 0.5 | AD47: 0.5 | AE47: 0.5 | AF47: 0.5 | AG47: 0.5 | AH47: 0.5 | AI47: 0.5 | AJ47: 0.5 | AK47: 0.5 | AL47: 0.5 | AM47: 0.5
A48: Cuba | B48: PWRTBATT01
A49: Cuba | B49: PWRTBATT02
...

Sheet OL
